Internal Server Error: /files/listfiles/
Traceback (most recent call last):
  File "C:\Users\RollPy\AppData\Local\pypoetry\Cache\virtualenvs\assistant-SImE5PKe-py3.12\Lib\site-packages\django\core\handlers\exception.py", line 55, in inner
    response = get_response(request)
               ^^^^^^^^^^^^^^^^^^^^^
  File "C:\Users\RollPy\AppData\Local\pypoetry\Cache\virtualenvs\assistant-SImE5PKe-py3.12\Lib\site-packages\django\core\handlers\base.py", line 197, in _get_response
    response = wrapped_callback(request, *callback_args, **callback_kwargs)
               ^^^^^^^^^^^^^^^^^^^^^^^^^^^^^^^^^^^^^^^^^^^^^^^^^^^^^^^^^^^^
  File "C:\Users\RollPy\Documents\GitHub\Django-Personal-Assistant\DPA\files\views.py", line 34, in get_filelist_from_drive
    print(f'REDIS_PRINT_______________{cache.hgetall('user_id')}')
                                       ^^^^^^^^^^^^^
  File "C:\Users\RollPy\AppData\Local\pypoetry\Cache\virtualenvs\assistant-SImE5PKe-py3.12\Lib\site-packages\django\utils\connection.py", line 15, in __getattr__
    return getattr(self._connections[self._alias], item)
           ^^^^^^^^^^^^^^^^^^^^^^^^^^^^^^^^^^^^^^^^^^^^^
AttributeError: 'RedisCache' object has no attribute 'hgetall'
Internal Server Error: /files/listfiles/
Traceback (most recent call last):
  File "C:\Users\RollPy\AppData\Local\pypoetry\Cache\virtualenvs\assistant-SImE5PKe-py3.12\Lib\site-packages\django\core\handlers\exception.py", line 55, in inner
    response = get_response(request)
               ^^^^^^^^^^^^^^^^^^^^^
  File "C:\Users\RollPy\AppData\Local\pypoetry\Cache\virtualenvs\assistant-SImE5PKe-py3.12\Lib\site-packages\django\core\handlers\base.py", line 197, in _get_response
    response = wrapped_callback(request, *callback_args, **callback_kwargs)
               ^^^^^^^^^^^^^^^^^^^^^^^^^^^^^^^^^^^^^^^^^^^^^^^^^^^^^^^^^^^^
  File "C:\Users\RollPy\Documents\GitHub\Django-Personal-Assistant\DPA\files\views.py", line 37, in get_filelist_from_drive
    print(f'REDIS_PRINT_______________{cache.get('user_id')}')
                                       ^^^^^^^^^^^^^^^^^^^^
  File "C:\Users\RollPy\AppData\Local\pypoetry\Cache\virtualenvs\assistant-SImE5PKe-py3.12\Lib\site-packages\redis\commands\core.py", line 1830, in get
    return self.execute_command("GET", name)
           ^^^^^^^^^^^^^^^^^^^^^^^^^^^^^^^^^
  File "C:\Users\RollPy\AppData\Local\pypoetry\Cache\virtualenvs\assistant-SImE5PKe-py3.12\Lib\site-packages\redis\client.py", line 545, in execute_command
    return conn.retry.call_with_retry(
           ^^^^^^^^^^^^^^^^^^^^^^^^^^^
  File "C:\Users\RollPy\AppData\Local\pypoetry\Cache\virtualenvs\assistant-SImE5PKe-py3.12\Lib\site-packages\redis\retry.py", line 46, in call_with_retry
    return do()
           ^^^^
  File "C:\Users\RollPy\AppData\Local\pypoetry\Cache\virtualenvs\assistant-SImE5PKe-py3.12\Lib\site-packages\redis\client.py", line 546, in <lambda>
    lambda: self._send_command_parse_response(
            ^^^^^^^^^^^^^^^^^^^^^^^^^^^^^^^^^^
  File "C:\Users\RollPy\AppData\Local\pypoetry\Cache\virtualenvs\assistant-SImE5PKe-py3.12\Lib\site-packages\redis\client.py", line 522, in _send_command_parse_response
    return self.parse_response(conn, command_name, **options)
           ^^^^^^^^^^^^^^^^^^^^^^^^^^^^^^^^^^^^^^^^^^^^^^^^^^
  File "C:\Users\RollPy\AppData\Local\pypoetry\Cache\virtualenvs\assistant-SImE5PKe-py3.12\Lib\site-packages\redis\client.py", line 562, in parse_response
    response = connection.read_response()
               ^^^^^^^^^^^^^^^^^^^^^^^^^^
  File "C:\Users\RollPy\AppData\Local\pypoetry\Cache\virtualenvs\assistant-SImE5PKe-py3.12\Lib\site-packages\redis\connection.py", line 536, in read_response
    raise response
redis.exceptions.ResponseError: WRONGTYPE Operation against a key holding the wrong kind of value
Internal Server Error: /files/listfiles/
Traceback (most recent call last):
  File "C:\Users\RollPy\AppData\Local\pypoetry\Cache\virtualenvs\assistant-SImE5PKe-py3.12\Lib\site-packages\django\core\handlers\exception.py", line 55, in inner
    response = get_response(request)
               ^^^^^^^^^^^^^^^^^^^^^
  File "C:\Users\RollPy\AppData\Local\pypoetry\Cache\virtualenvs\assistant-SImE5PKe-py3.12\Lib\site-packages\django\core\handlers\base.py", line 197, in _get_response
    response = wrapped_callback(request, *callback_args, **callback_kwargs)
               ^^^^^^^^^^^^^^^^^^^^^^^^^^^^^^^^^^^^^^^^^^^^^^^^^^^^^^^^^^^^
  File "C:\Users\RollPy\Documents\GitHub\Django-Personal-Assistant\DPA\files\views.py", line 38, in get_filelist_from_drive
    print(f'REDIS_PRINT_______________{cache.get('some_key', 'some_value')}')
                                       ^^^^^^^^^^^^^^^^^^^^^^^^^^^^^^^^^^^
TypeError: BasicKeyCommands.get() takes 2 positional arguments but 3 were given
Internal Server Error: /files/listfiles/
Traceback (most recent call last):
  File "C:\Users\RollPy\AppData\Local\pypoetry\Cache\virtualenvs\assistant-SImE5PKe-py3.12\Lib\site-packages\django\core\handlers\exception.py", line 55, in inner
    response = get_response(request)
               ^^^^^^^^^^^^^^^^^^^^^
  File "C:\Users\RollPy\AppData\Local\pypoetry\Cache\virtualenvs\assistant-SImE5PKe-py3.12\Lib\site-packages\django\core\handlers\base.py", line 197, in _get_response
    response = wrapped_callback(request, *callback_args, **callback_kwargs)
               ^^^^^^^^^^^^^^^^^^^^^^^^^^^^^^^^^^^^^^^^^^^^^^^^^^^^^^^^^^^^
  File "C:\Users\RollPy\Documents\GitHub\Django-Personal-Assistant\DPA\files\views.py", line 37, in get_filelist_from_drive
    cache.set('some_key')
TypeError: BasicKeyCommands.set() missing 1 required positional argument: 'value'
Internal Server Error: /files/listfiles/
Traceback (most recent call last):
  File "C:\Users\RollPy\AppData\Local\pypoetry\Cache\virtualenvs\assistant-SImE5PKe-py3.12\Lib\site-packages\redis\connection.py", line 67, in pack
    output.append(hiredis.pack_command(args))
                  ^^^^^^^^^^^^^^^^^^^^^^^^^^
TypeError: A tuple item must be str, int, float or bytes.

During handling of the above exception, another exception occurred:

Traceback (most recent call last):
  File "C:\Users\RollPy\AppData\Local\pypoetry\Cache\virtualenvs\assistant-SImE5PKe-py3.12\Lib\site-packages\django\core\handlers\exception.py", line 55, in inner
    response = get_response(request)
               ^^^^^^^^^^^^^^^^^^^^^
  File "C:\Users\RollPy\AppData\Local\pypoetry\Cache\virtualenvs\assistant-SImE5PKe-py3.12\Lib\site-packages\django\core\handlers\base.py", line 197, in _get_response
    response = wrapped_callback(request, *callback_args, **callback_kwargs)
               ^^^^^^^^^^^^^^^^^^^^^^^^^^^^^^^^^^^^^^^^^^^^^^^^^^^^^^^^^^^^
  File "C:\Users\RollPy\Documents\GitHub\Django-Personal-Assistant\DPA\files\views.py", line 41, in get_filelist_from_drive
    cache.set('some_key_for_dict', value_dict)
  File "C:\Users\RollPy\AppData\Local\pypoetry\Cache\virtualenvs\assistant-SImE5PKe-py3.12\Lib\site-packages\redis\commands\core.py", line 2342, in set
    return self.execute_command("SET", *pieces, **options)
           ^^^^^^^^^^^^^^^^^^^^^^^^^^^^^^^^^^^^^^^^^^^^^^^
  File "C:\Users\RollPy\AppData\Local\pypoetry\Cache\virtualenvs\assistant-SImE5PKe-py3.12\Lib\site-packages\redis\client.py", line 545, in execute_command
    return conn.retry.call_with_retry(
           ^^^^^^^^^^^^^^^^^^^^^^^^^^^
  File "C:\Users\RollPy\AppData\Local\pypoetry\Cache\virtualenvs\assistant-SImE5PKe-py3.12\Lib\site-packages\redis\retry.py", line 46, in call_with_retry
    return do()
           ^^^^
  File "C:\Users\RollPy\AppData\Local\pypoetry\Cache\virtualenvs\assistant-SImE5PKe-py3.12\Lib\site-packages\redis\client.py", line 546, in <lambda>
    lambda: self._send_command_parse_response(
            ^^^^^^^^^^^^^^^^^^^^^^^^^^^^^^^^^^
  File "C:\Users\RollPy\AppData\Local\pypoetry\Cache\virtualenvs\assistant-SImE5PKe-py3.12\Lib\site-packages\redis\client.py", line 521, in _send_command_parse_response
    conn.send_command(*args)
  File "C:\Users\RollPy\AppData\Local\pypoetry\Cache\virtualenvs\assistant-SImE5PKe-py3.12\Lib\site-packages\redis\connection.py", line 477, in send_command
    self._command_packer.pack(*args),
    ^^^^^^^^^^^^^^^^^^^^^^^^^^^^^^^^
  File "C:\Users\RollPy\AppData\Local\pypoetry\Cache\virtualenvs\assistant-SImE5PKe-py3.12\Lib\site-packages\redis\connection.py", line 70, in pack
    raise DataError(value).with_traceback(traceback)
  File "C:\Users\RollPy\AppData\Local\pypoetry\Cache\virtualenvs\assistant-SImE5PKe-py3.12\Lib\site-packages\redis\connection.py", line 67, in pack
    output.append(hiredis.pack_command(args))
                  ^^^^^^^^^^^^^^^^^^^^^^^^^^
redis.exceptions.DataError: A tuple item must be str, int, float or bytes.
Internal Server Error: /files/listfiles/
Traceback (most recent call last):
  File "C:\Users\RollPy\AppData\Local\pypoetry\Cache\virtualenvs\assistant-SImE5PKe-py3.12\Lib\site-packages\redis\connection.py", line 67, in pack
    output.append(hiredis.pack_command(args))
                  ^^^^^^^^^^^^^^^^^^^^^^^^^^
TypeError: A tuple item must be str, int, float or bytes.

During handling of the above exception, another exception occurred:

Traceback (most recent call last):
  File "C:\Users\RollPy\AppData\Local\pypoetry\Cache\virtualenvs\assistant-SImE5PKe-py3.12\Lib\site-packages\django\core\handlers\exception.py", line 55, in inner
    response = get_response(request)
               ^^^^^^^^^^^^^^^^^^^^^
  File "C:\Users\RollPy\AppData\Local\pypoetry\Cache\virtualenvs\assistant-SImE5PKe-py3.12\Lib\site-packages\django\core\handlers\base.py", line 197, in _get_response
    response = wrapped_callback(request, *callback_args, **callback_kwargs)
               ^^^^^^^^^^^^^^^^^^^^^^^^^^^^^^^^^^^^^^^^^^^^^^^^^^^^^^^^^^^^
  File "C:\Users\RollPy\Documents\GitHub\Django-Personal-Assistant\DPA\files\views.py", line 41, in get_filelist_from_drive
    cache.set('some_key_for_dict', value_dict)
  File "C:\Users\RollPy\AppData\Local\pypoetry\Cache\virtualenvs\assistant-SImE5PKe-py3.12\Lib\site-packages\redis\commands\core.py", line 2342, in set
    return self.execute_command("SET", *pieces, **options)
           ^^^^^^^^^^^^^^^^^^^^^^^^^^^^^^^^^^^^^^^^^^^^^^^
  File "C:\Users\RollPy\AppData\Local\pypoetry\Cache\virtualenvs\assistant-SImE5PKe-py3.12\Lib\site-packages\redis\client.py", line 545, in execute_command
    return conn.retry.call_with_retry(
           ^^^^^^^^^^^^^^^^^^^^^^^^^^^
  File "C:\Users\RollPy\AppData\Local\pypoetry\Cache\virtualenvs\assistant-SImE5PKe-py3.12\Lib\site-packages\redis\retry.py", line 46, in call_with_retry
    return do()
           ^^^^
  File "C:\Users\RollPy\AppData\Local\pypoetry\Cache\virtualenvs\assistant-SImE5PKe-py3.12\Lib\site-packages\redis\client.py", line 546, in <lambda>
    lambda: self._send_command_parse_response(
            ^^^^^^^^^^^^^^^^^^^^^^^^^^^^^^^^^^
  File "C:\Users\RollPy\AppData\Local\pypoetry\Cache\virtualenvs\assistant-SImE5PKe-py3.12\Lib\site-packages\redis\client.py", line 521, in _send_command_parse_response
    conn.send_command(*args)
  File "C:\Users\RollPy\AppData\Local\pypoetry\Cache\virtualenvs\assistant-SImE5PKe-py3.12\Lib\site-packages\redis\connection.py", line 477, in send_command
    self._command_packer.pack(*args),
    ^^^^^^^^^^^^^^^^^^^^^^^^^^^^^^^^
  File "C:\Users\RollPy\AppData\Local\pypoetry\Cache\virtualenvs\assistant-SImE5PKe-py3.12\Lib\site-packages\redis\connection.py", line 70, in pack
    raise DataError(value).with_traceback(traceback)
  File "C:\Users\RollPy\AppData\Local\pypoetry\Cache\virtualenvs\assistant-SImE5PKe-py3.12\Lib\site-packages\redis\connection.py", line 67, in pack
    output.append(hiredis.pack_command(args))
                  ^^^^^^^^^^^^^^^^^^^^^^^^^^
redis.exceptions.DataError: A tuple item must be str, int, float or bytes.
Internal Server Error: /files/listfiles/
Traceback (most recent call last):
  File "C:\Users\RollPy\AppData\Local\pypoetry\Cache\virtualenvs\assistant-SImE5PKe-py3.12\Lib\site-packages\django\core\handlers\exception.py", line 55, in inner
    response = get_response(request)
               ^^^^^^^^^^^^^^^^^^^^^
  File "C:\Users\RollPy\AppData\Local\pypoetry\Cache\virtualenvs\assistant-SImE5PKe-py3.12\Lib\site-packages\django\core\handlers\base.py", line 197, in _get_response
    response = wrapped_callback(request, *callback_args, **callback_kwargs)
               ^^^^^^^^^^^^^^^^^^^^^^^^^^^^^^^^^^^^^^^^^^^^^^^^^^^^^^^^^^^^
  File "C:\Users\RollPy\Documents\GitHub\Django-Personal-Assistant\DPA\files\views.py", line 34, in get_filelist_from_drive
    documents, videos, images, other = async_to_sync(get_file_list_from_drive)(get_folder_id_by_user(request.user))
                                       ^^^^^^^^^^^^^^^^^^^^^^^^^^^^^^^^^^^^^^^^^^^^^^^^^^^^^^^^^^^^^^^^^^^^^^^^^^^^
  File "C:\Users\RollPy\AppData\Local\pypoetry\Cache\virtualenvs\assistant-SImE5PKe-py3.12\Lib\site-packages\asgiref\sync.py", line 254, in __call__
    return call_result.result()
           ^^^^^^^^^^^^^^^^^^^^
  File "C:\Users\RollPy\AppData\Local\Programs\Python\Python312\Lib\concurrent\futures\_base.py", line 449, in result
    return self.__get_result()
           ^^^^^^^^^^^^^^^^^^^
  File "C:\Users\RollPy\AppData\Local\Programs\Python\Python312\Lib\concurrent\futures\_base.py", line 401, in __get_result
    raise self._exception
  File "C:\Users\RollPy\AppData\Local\pypoetry\Cache\virtualenvs\assistant-SImE5PKe-py3.12\Lib\site-packages\asgiref\sync.py", line 331, in main_wrap
    result = await self.awaitable(*args, **kwargs)
             ^^^^^^^^^^^^^^^^^^^^^^^^^^^^^^^^^^^^^
  File "C:\Users\RollPy\Documents\GitHub\Django-Personal-Assistant\DPA\files\views.py", line 73, in get_file_list_from_drive
    print(list(documents, videos, images, other))
          ^^^^^^^^^^^^^^^^^^^^^^^^^^^^^^^^^^^^^^
TypeError: list expected at most 1 argument, got 4
Internal Server Error: /files/listfiles/
Traceback (most recent call last):
  File "C:\Users\RollPy\AppData\Local\pypoetry\Cache\virtualenvs\assistant-SImE5PKe-py3.12\Lib\site-packages\django\core\handlers\exception.py", line 55, in inner
    response = get_response(request)
               ^^^^^^^^^^^^^^^^^^^^^
  File "C:\Users\RollPy\AppData\Local\pypoetry\Cache\virtualenvs\assistant-SImE5PKe-py3.12\Lib\site-packages\django\core\handlers\base.py", line 197, in _get_response
    response = wrapped_callback(request, *callback_args, **callback_kwargs)
               ^^^^^^^^^^^^^^^^^^^^^^^^^^^^^^^^^^^^^^^^^^^^^^^^^^^^^^^^^^^^
  File "C:\Users\RollPy\Documents\GitHub\Django-Personal-Assistant\DPA\files\views.py", line 34, in get_filelist_from_drive
    documents, videos, images, other = async_to_sync(get_file_list_from_drive)(get_folder_id_by_user(request.user))
                                       ^^^^^^^^^^^^^^^^^^^^^^^^^^^^^^^^^^^^^^^^^^^^^^^^^^^^^^^^^^^^^^^^^^^^^^^^^^^^
  File "C:\Users\RollPy\AppData\Local\pypoetry\Cache\virtualenvs\assistant-SImE5PKe-py3.12\Lib\site-packages\asgiref\sync.py", line 254, in __call__
    return call_result.result()
           ^^^^^^^^^^^^^^^^^^^^
  File "C:\Users\RollPy\AppData\Local\Programs\Python\Python312\Lib\concurrent\futures\_base.py", line 449, in result
    return self.__get_result()
           ^^^^^^^^^^^^^^^^^^^
  File "C:\Users\RollPy\AppData\Local\Programs\Python\Python312\Lib\concurrent\futures\_base.py", line 401, in __get_result
    raise self._exception
  File "C:\Users\RollPy\AppData\Local\pypoetry\Cache\virtualenvs\assistant-SImE5PKe-py3.12\Lib\site-packages\asgiref\sync.py", line 331, in main_wrap
    result = await self.awaitable(*args, **kwargs)
             ^^^^^^^^^^^^^^^^^^^^^^^^^^^^^^^^^^^^^
  File "C:\Users\RollPy\Documents\GitHub\Django-Personal-Assistant\DPA\files\views.py", line 73, in get_file_list_from_drive
    print(list(documents, videos, images, other))
          ^^^^^^^^^^^^^^^^^^^^^^^^^^^^^^^^^^^^^^
TypeError: list expected at most 1 argument, got 4
Internal Server Error: /files/listfiles/
Traceback (most recent call last):
  File "C:\Users\RollPy\AppData\Local\pypoetry\Cache\virtualenvs\assistant-SImE5PKe-py3.12\Lib\site-packages\django\core\handlers\exception.py", line 55, in inner
    response = get_response(request)
               ^^^^^^^^^^^^^^^^^^^^^
  File "C:\Users\RollPy\AppData\Local\pypoetry\Cache\virtualenvs\assistant-SImE5PKe-py3.12\Lib\site-packages\django\core\handlers\base.py", line 197, in _get_response
    response = wrapped_callback(request, *callback_args, **callback_kwargs)
               ^^^^^^^^^^^^^^^^^^^^^^^^^^^^^^^^^^^^^^^^^^^^^^^^^^^^^^^^^^^^
  File "C:\Users\RollPy\Documents\GitHub\Django-Personal-Assistant\DPA\files\views.py", line 34, in get_filelist_from_drive
    documents, videos, images, other = async_to_sync(get_file_list_from_drive)(get_folder_id_by_user(request.user))
                                       ^^^^^^^^^^^^^^^^^^^^^^^^^^^^^^^^^^^^^^^^^^^^^^^^^^^^^^^^^^^^^^^^^^^^^^^^^^^^
  File "C:\Users\RollPy\AppData\Local\pypoetry\Cache\virtualenvs\assistant-SImE5PKe-py3.12\Lib\site-packages\asgiref\sync.py", line 254, in __call__
    return call_result.result()
           ^^^^^^^^^^^^^^^^^^^^
  File "C:\Users\RollPy\AppData\Local\Programs\Python\Python312\Lib\concurrent\futures\_base.py", line 449, in result
    return self.__get_result()
           ^^^^^^^^^^^^^^^^^^^
  File "C:\Users\RollPy\AppData\Local\Programs\Python\Python312\Lib\concurrent\futures\_base.py", line 401, in __get_result
    raise self._exception
  File "C:\Users\RollPy\AppData\Local\pypoetry\Cache\virtualenvs\assistant-SImE5PKe-py3.12\Lib\site-packages\asgiref\sync.py", line 331, in main_wrap
    result = await self.awaitable(*args, **kwargs)
             ^^^^^^^^^^^^^^^^^^^^^^^^^^^^^^^^^^^^^
  File "C:\Users\RollPy\Documents\GitHub\Django-Personal-Assistant\DPA\files\views.py", line 73, in get_file_list_from_drive
    print(list(documents, videos, images, other))
          ^^^^^^^^^^^^^^^^^^^^^^^^^^^^^^^^^^^^^^
TypeError: list expected at most 1 argument, got 4
Internal Server Error: /files/listfiles/
Traceback (most recent call last):
  File "C:\Users\RollPy\AppData\Local\pypoetry\Cache\virtualenvs\assistant-SImE5PKe-py3.12\Lib\site-packages\django\core\handlers\exception.py", line 55, in inner
    response = get_response(request)
               ^^^^^^^^^^^^^^^^^^^^^
  File "C:\Users\RollPy\AppData\Local\pypoetry\Cache\virtualenvs\assistant-SImE5PKe-py3.12\Lib\site-packages\django\core\handlers\base.py", line 197, in _get_response
    response = wrapped_callback(request, *callback_args, **callback_kwargs)
               ^^^^^^^^^^^^^^^^^^^^^^^^^^^^^^^^^^^^^^^^^^^^^^^^^^^^^^^^^^^^
  File "C:\Users\RollPy\Documents\GitHub\Django-Personal-Assistant\DPA\files\views.py", line 35, in get_filelist_from_drive
    cache.set(request.user.id, data, timelimit=3600)
  File "C:\Users\RollPy\AppData\Local\pypoetry\Cache\virtualenvs\assistant-SImE5PKe-py3.12\Lib\site-packages\django_redis\cache.py", line 29, in _decorator
    return method(self, *args, **kwargs)
           ^^^^^^^^^^^^^^^^^^^^^^^^^^^^^
  File "C:\Users\RollPy\AppData\Local\pypoetry\Cache\virtualenvs\assistant-SImE5PKe-py3.12\Lib\site-packages\django_redis\cache.py", line 81, in set
    return self.client.set(*args, **kwargs)
           ^^^^^^^^^^^^^^^^^^^^^^^^^^^^^^^^
TypeError: DefaultClient.set() got an unexpected keyword argument 'timelimit'
Internal Server Error: /files/listfiles/
Traceback (most recent call last):
  File "C:\Users\RollPy\AppData\Local\pypoetry\Cache\virtualenvs\assistant-SImE5PKe-py3.12\Lib\site-packages\django\core\handlers\exception.py", line 55, in inner
    response = get_response(request)
               ^^^^^^^^^^^^^^^^^^^^^
  File "C:\Users\RollPy\AppData\Local\pypoetry\Cache\virtualenvs\assistant-SImE5PKe-py3.12\Lib\site-packages\django\core\handlers\base.py", line 197, in _get_response
    response = wrapped_callback(request, *callback_args, **callback_kwargs)
               ^^^^^^^^^^^^^^^^^^^^^^^^^^^^^^^^^^^^^^^^^^^^^^^^^^^^^^^^^^^^
  File "C:\Users\RollPy\Documents\GitHub\Django-Personal-Assistant\DPA\files\views.py", line 37, in get_filelist_from_drive
    return render(request, 'files/async_show_files_list.html', {'data': data})
           ^^^^^^^^^^^^^^^^^^^^^^^^^^^^^^^^^^^^^^^^^^^^^^^^^^^^^^^^^^^^^^^^^^^
  File "C:\Users\RollPy\AppData\Local\pypoetry\Cache\virtualenvs\assistant-SImE5PKe-py3.12\Lib\site-packages\django\shortcuts.py", line 25, in render
    content = loader.render_to_string(template_name, context, request, using=using)
              ^^^^^^^^^^^^^^^^^^^^^^^^^^^^^^^^^^^^^^^^^^^^^^^^^^^^^^^^^^^^^^^^^^^^^
  File "C:\Users\RollPy\AppData\Local\pypoetry\Cache\virtualenvs\assistant-SImE5PKe-py3.12\Lib\site-packages\django\template\loader.py", line 61, in render_to_string
    template = get_template(template_name, using=using)
               ^^^^^^^^^^^^^^^^^^^^^^^^^^^^^^^^^^^^^^^^
  File "C:\Users\RollPy\AppData\Local\pypoetry\Cache\virtualenvs\assistant-SImE5PKe-py3.12\Lib\site-packages\django\template\loader.py", line 15, in get_template
    return engine.get_template(template_name)
           ^^^^^^^^^^^^^^^^^^^^^^^^^^^^^^^^^^
  File "C:\Users\RollPy\AppData\Local\pypoetry\Cache\virtualenvs\assistant-SImE5PKe-py3.12\Lib\site-packages\django\template\backends\django.py", line 33, in get_template
    return Template(self.engine.get_template(template_name), self)
                    ^^^^^^^^^^^^^^^^^^^^^^^^^^^^^^^^^^^^^^^
  File "C:\Users\RollPy\AppData\Local\pypoetry\Cache\virtualenvs\assistant-SImE5PKe-py3.12\Lib\site-packages\django\template\engine.py", line 177, in get_template
    template, origin = self.find_template(template_name)
                       ^^^^^^^^^^^^^^^^^^^^^^^^^^^^^^^^^
  File "C:\Users\RollPy\AppData\Local\pypoetry\Cache\virtualenvs\assistant-SImE5PKe-py3.12\Lib\site-packages\django\template\engine.py", line 159, in find_template
    template = loader.get_template(name, skip=skip)
               ^^^^^^^^^^^^^^^^^^^^^^^^^^^^^^^^^^^^
  File "C:\Users\RollPy\AppData\Local\pypoetry\Cache\virtualenvs\assistant-SImE5PKe-py3.12\Lib\site-packages\django\template\loaders\cached.py", line 57, in get_template
    template = super().get_template(template_name, skip)
               ^^^^^^^^^^^^^^^^^^^^^^^^^^^^^^^^^^^^^^^^^
  File "C:\Users\RollPy\AppData\Local\pypoetry\Cache\virtualenvs\assistant-SImE5PKe-py3.12\Lib\site-packages\django\template\loaders\base.py", line 28, in get_template
    return Template(
           ^^^^^^^^^
  File "C:\Users\RollPy\AppData\Local\pypoetry\Cache\virtualenvs\assistant-SImE5PKe-py3.12\Lib\site-packages\django\template\base.py", line 154, in __init__
    self.nodelist = self.compile_nodelist()
                    ^^^^^^^^^^^^^^^^^^^^^^^
  File "C:\Users\RollPy\AppData\Local\pypoetry\Cache\virtualenvs\assistant-SImE5PKe-py3.12\Lib\site-packages\django\template\base.py", line 196, in compile_nodelist
    return parser.parse()
           ^^^^^^^^^^^^^^
  File "C:\Users\RollPy\AppData\Local\pypoetry\Cache\virtualenvs\assistant-SImE5PKe-py3.12\Lib\site-packages\django\template\base.py", line 510, in parse
    raise self.error(token, e)
  File "C:\Users\RollPy\AppData\Local\pypoetry\Cache\virtualenvs\assistant-SImE5PKe-py3.12\Lib\site-packages\django\template\base.py", line 508, in parse
    compiled_result = compile_func(self, token)
                      ^^^^^^^^^^^^^^^^^^^^^^^^^
  File "C:\Users\RollPy\AppData\Local\pypoetry\Cache\virtualenvs\assistant-SImE5PKe-py3.12\Lib\site-packages\django\template\defaulttags.py", line 860, in do_for
    sequence = parser.compile_filter(bits[in_index + 1])
               ^^^^^^^^^^^^^^^^^^^^^^^^^^^^^^^^^^^^^^^^^
  File "C:\Users\RollPy\AppData\Local\pypoetry\Cache\virtualenvs\assistant-SImE5PKe-py3.12\Lib\site-packages\django\template\base.py", line 597, in compile_filter
    return FilterExpression(token, self)
           ^^^^^^^^^^^^^^^^^^^^^^^^^^^^^
  File "C:\Users\RollPy\AppData\Local\pypoetry\Cache\virtualenvs\assistant-SImE5PKe-py3.12\Lib\site-packages\django\template\base.py", line 698, in __init__
    raise TemplateSyntaxError(
django.template.exceptions.TemplateSyntaxError: Could not parse the remainder: '['documents'].items' from 'data['documents'].items'
Internal Server Error: /files/listfiles/
Traceback (most recent call last):
  File "C:\Users\RollPy\AppData\Local\pypoetry\Cache\virtualenvs\assistant-SImE5PKe-py3.12\Lib\site-packages\django\core\handlers\exception.py", line 55, in inner
    response = get_response(request)
               ^^^^^^^^^^^^^^^^^^^^^
  File "C:\Users\RollPy\AppData\Local\pypoetry\Cache\virtualenvs\assistant-SImE5PKe-py3.12\Lib\site-packages\django\core\handlers\base.py", line 197, in _get_response
    response = wrapped_callback(request, *callback_args, **callback_kwargs)
               ^^^^^^^^^^^^^^^^^^^^^^^^^^^^^^^^^^^^^^^^^^^^^^^^^^^^^^^^^^^^
  File "C:\Users\RollPy\Documents\GitHub\Django-Personal-Assistant\DPA\files\views.py", line 38, in get_filelist_from_drive
    return render(request, 'files/async_show_files_list.html', {'data': data})
           ^^^^^^^^^^^^^^^^^^^^^^^^^^^^^^^^^^^^^^^^^^^^^^^^^^^^^^^^^^^^^^^^^^^
  File "C:\Users\RollPy\AppData\Local\pypoetry\Cache\virtualenvs\assistant-SImE5PKe-py3.12\Lib\site-packages\django\shortcuts.py", line 25, in render
    content = loader.render_to_string(template_name, context, request, using=using)
              ^^^^^^^^^^^^^^^^^^^^^^^^^^^^^^^^^^^^^^^^^^^^^^^^^^^^^^^^^^^^^^^^^^^^^
  File "C:\Users\RollPy\AppData\Local\pypoetry\Cache\virtualenvs\assistant-SImE5PKe-py3.12\Lib\site-packages\django\template\loader.py", line 61, in render_to_string
    template = get_template(template_name, using=using)
               ^^^^^^^^^^^^^^^^^^^^^^^^^^^^^^^^^^^^^^^^
  File "C:\Users\RollPy\AppData\Local\pypoetry\Cache\virtualenvs\assistant-SImE5PKe-py3.12\Lib\site-packages\django\template\loader.py", line 15, in get_template
    return engine.get_template(template_name)
           ^^^^^^^^^^^^^^^^^^^^^^^^^^^^^^^^^^
  File "C:\Users\RollPy\AppData\Local\pypoetry\Cache\virtualenvs\assistant-SImE5PKe-py3.12\Lib\site-packages\django\template\backends\django.py", line 33, in get_template
    return Template(self.engine.get_template(template_name), self)
                    ^^^^^^^^^^^^^^^^^^^^^^^^^^^^^^^^^^^^^^^
  File "C:\Users\RollPy\AppData\Local\pypoetry\Cache\virtualenvs\assistant-SImE5PKe-py3.12\Lib\site-packages\django\template\engine.py", line 177, in get_template
    template, origin = self.find_template(template_name)
                       ^^^^^^^^^^^^^^^^^^^^^^^^^^^^^^^^^
  File "C:\Users\RollPy\AppData\Local\pypoetry\Cache\virtualenvs\assistant-SImE5PKe-py3.12\Lib\site-packages\django\template\engine.py", line 159, in find_template
    template = loader.get_template(name, skip=skip)
               ^^^^^^^^^^^^^^^^^^^^^^^^^^^^^^^^^^^^
  File "C:\Users\RollPy\AppData\Local\pypoetry\Cache\virtualenvs\assistant-SImE5PKe-py3.12\Lib\site-packages\django\template\loaders\cached.py", line 57, in get_template
    template = super().get_template(template_name, skip)
               ^^^^^^^^^^^^^^^^^^^^^^^^^^^^^^^^^^^^^^^^^
  File "C:\Users\RollPy\AppData\Local\pypoetry\Cache\virtualenvs\assistant-SImE5PKe-py3.12\Lib\site-packages\django\template\loaders\base.py", line 28, in get_template
    return Template(
           ^^^^^^^^^
  File "C:\Users\RollPy\AppData\Local\pypoetry\Cache\virtualenvs\assistant-SImE5PKe-py3.12\Lib\site-packages\django\template\base.py", line 154, in __init__
    self.nodelist = self.compile_nodelist()
                    ^^^^^^^^^^^^^^^^^^^^^^^
  File "C:\Users\RollPy\AppData\Local\pypoetry\Cache\virtualenvs\assistant-SImE5PKe-py3.12\Lib\site-packages\django\template\base.py", line 196, in compile_nodelist
    return parser.parse()
           ^^^^^^^^^^^^^^
  File "C:\Users\RollPy\AppData\Local\pypoetry\Cache\virtualenvs\assistant-SImE5PKe-py3.12\Lib\site-packages\django\template\base.py", line 510, in parse
    raise self.error(token, e)
  File "C:\Users\RollPy\AppData\Local\pypoetry\Cache\virtualenvs\assistant-SImE5PKe-py3.12\Lib\site-packages\django\template\base.py", line 508, in parse
    compiled_result = compile_func(self, token)
                      ^^^^^^^^^^^^^^^^^^^^^^^^^
  File "C:\Users\RollPy\AppData\Local\pypoetry\Cache\virtualenvs\assistant-SImE5PKe-py3.12\Lib\site-packages\django\template\defaulttags.py", line 860, in do_for
    sequence = parser.compile_filter(bits[in_index + 1])
               ^^^^^^^^^^^^^^^^^^^^^^^^^^^^^^^^^^^^^^^^^
  File "C:\Users\RollPy\AppData\Local\pypoetry\Cache\virtualenvs\assistant-SImE5PKe-py3.12\Lib\site-packages\django\template\base.py", line 597, in compile_filter
    return FilterExpression(token, self)
           ^^^^^^^^^^^^^^^^^^^^^^^^^^^^^
  File "C:\Users\RollPy\AppData\Local\pypoetry\Cache\virtualenvs\assistant-SImE5PKe-py3.12\Lib\site-packages\django\template\base.py", line 698, in __init__
    raise TemplateSyntaxError(
django.template.exceptions.TemplateSyntaxError: Could not parse the remainder: '['documents'].items' from 'data['documents'].items'
Internal Server Error: /files/listfiles/
Traceback (most recent call last):
  File "C:\Users\RollPy\AppData\Local\pypoetry\Cache\virtualenvs\assistant-SImE5PKe-py3.12\Lib\site-packages\django\core\handlers\exception.py", line 55, in inner
    response = get_response(request)
               ^^^^^^^^^^^^^^^^^^^^^
  File "C:\Users\RollPy\AppData\Local\pypoetry\Cache\virtualenvs\assistant-SImE5PKe-py3.12\Lib\site-packages\django\core\handlers\base.py", line 197, in _get_response
    response = wrapped_callback(request, *callback_args, **callback_kwargs)
               ^^^^^^^^^^^^^^^^^^^^^^^^^^^^^^^^^^^^^^^^^^^^^^^^^^^^^^^^^^^^
  File "C:\Users\RollPy\Documents\GitHub\Django-Personal-Assistant\DPA\files\views.py", line 40, in get_filelist_from_drive
    'images': data['images'], 'video': data['video'], 'other': data['other']
                                       ~~~~^^^^^^^^^
KeyError: 'video'
Internal Server Error: /files/upload/
Traceback (most recent call last):
  File "C:\Users\RollPy\AppData\Local\pypoetry\Cache\virtualenvs\assistant-SImE5PKe-py3.12\Lib\site-packages\django\core\handlers\exception.py", line 55, in inner
    response = get_response(request)
               ^^^^^^^^^^^^^^^^^^^^^
  File "C:\Users\RollPy\AppData\Local\pypoetry\Cache\virtualenvs\assistant-SImE5PKe-py3.12\Lib\site-packages\django\core\handlers\base.py", line 197, in _get_response
    response = wrapped_callback(request, *callback_args, **callback_kwargs)
               ^^^^^^^^^^^^^^^^^^^^^^^^^^^^^^^^^^^^^^^^^^^^^^^^^^^^^^^^^^^^
  File "C:\Users\RollPy\Documents\GitHub\Django-Personal-Assistant\DPA\files\views.py", line 134, in upload_file
    return redirect('files:show_images')
           ^^^^^^^^^^^^^^^^^^^^^^^^^^^^^
  File "C:\Users\RollPy\AppData\Local\pypoetry\Cache\virtualenvs\assistant-SImE5PKe-py3.12\Lib\site-packages\django\shortcuts.py", line 49, in redirect
    return redirect_class(resolve_url(to, *args, **kwargs))
                          ^^^^^^^^^^^^^^^^^^^^^^^^^^^^^^^^
  File "C:\Users\RollPy\AppData\Local\pypoetry\Cache\virtualenvs\assistant-SImE5PKe-py3.12\Lib\site-packages\django\shortcuts.py", line 180, in resolve_url
    return reverse(to, args=args, kwargs=kwargs)
           ^^^^^^^^^^^^^^^^^^^^^^^^^^^^^^^^^^^^^
  File "C:\Users\RollPy\AppData\Local\pypoetry\Cache\virtualenvs\assistant-SImE5PKe-py3.12\Lib\site-packages\django\urls\base.py", line 88, in reverse
    return resolver._reverse_with_prefix(view, prefix, *args, **kwargs)
           ^^^^^^^^^^^^^^^^^^^^^^^^^^^^^^^^^^^^^^^^^^^^^^^^^^^^^^^^^^^^
  File "C:\Users\RollPy\AppData\Local\pypoetry\Cache\virtualenvs\assistant-SImE5PKe-py3.12\Lib\site-packages\django\urls\resolvers.py", line 851, in _reverse_with_prefix
    raise NoReverseMatch(msg)
django.urls.exceptions.NoReverseMatch: Reverse for 'show_images' not found. 'show_images' is not a valid view function or pattern name.
Internal Server Error: /files/listfiles/
Traceback (most recent call last):
  File "C:\Users\RollPy\AppData\Local\pypoetry\Cache\virtualenvs\assistant-SImE5PKe-py3.12\Lib\site-packages\django\core\handlers\exception.py", line 55, in inner
    response = get_response(request)
               ^^^^^^^^^^^^^^^^^^^^^
  File "C:\Users\RollPy\AppData\Local\pypoetry\Cache\virtualenvs\assistant-SImE5PKe-py3.12\Lib\site-packages\django\core\handlers\base.py", line 197, in _get_response
    response = wrapped_callback(request, *callback_args, **callback_kwargs)
               ^^^^^^^^^^^^^^^^^^^^^^^^^^^^^^^^^^^^^^^^^^^^^^^^^^^^^^^^^^^^
  File "C:\Users\RollPy\Documents\GitHub\Django-Personal-Assistant\DPA\files\views.py", line 43, in get_filelist_from_drive
    return render(request, 'files/base.html',
           ^^^^^^^^^^^^^^^^^^^^^^^^^^^^^^^^^^
  File "C:\Users\RollPy\AppData\Local\pypoetry\Cache\virtualenvs\assistant-SImE5PKe-py3.12\Lib\site-packages\django\shortcuts.py", line 25, in render
    content = loader.render_to_string(template_name, context, request, using=using)
              ^^^^^^^^^^^^^^^^^^^^^^^^^^^^^^^^^^^^^^^^^^^^^^^^^^^^^^^^^^^^^^^^^^^^^
  File "C:\Users\RollPy\AppData\Local\pypoetry\Cache\virtualenvs\assistant-SImE5PKe-py3.12\Lib\site-packages\django\template\loader.py", line 61, in render_to_string
    template = get_template(template_name, using=using)
               ^^^^^^^^^^^^^^^^^^^^^^^^^^^^^^^^^^^^^^^^
  File "C:\Users\RollPy\AppData\Local\pypoetry\Cache\virtualenvs\assistant-SImE5PKe-py3.12\Lib\site-packages\django\template\loader.py", line 19, in get_template
    raise TemplateDoesNotExist(template_name, chain=chain)
django.template.exceptions.TemplateDoesNotExist: files/base.html
Internal Server Error: /files/listfiles/
Traceback (most recent call last):
  File "C:\Users\RollPy\AppData\Local\pypoetry\Cache\virtualenvs\assistant-SImE5PKe-py3.12\Lib\site-packages\django\core\handlers\exception.py", line 55, in inner
    response = get_response(request)
               ^^^^^^^^^^^^^^^^^^^^^
  File "C:\Users\RollPy\AppData\Local\pypoetry\Cache\virtualenvs\assistant-SImE5PKe-py3.12\Lib\site-packages\django\core\handlers\base.py", line 197, in _get_response
    response = wrapped_callback(request, *callback_args, **callback_kwargs)
               ^^^^^^^^^^^^^^^^^^^^^^^^^^^^^^^^^^^^^^^^^^^^^^^^^^^^^^^^^^^^
  File "C:\Users\RollPy\Documents\GitHub\Django-Personal-Assistant\DPA\files\views.py", line 43, in get_filelist_from_drive
    return render(request, 'files/base_for_files.html',
           ^^^^^^^^^^^^^^^^^^^^^^^^^^^^^^^^^^^^^^^^^^^^
  File "C:\Users\RollPy\AppData\Local\pypoetry\Cache\virtualenvs\assistant-SImE5PKe-py3.12\Lib\site-packages\django\shortcuts.py", line 25, in render
    content = loader.render_to_string(template_name, context, request, using=using)
              ^^^^^^^^^^^^^^^^^^^^^^^^^^^^^^^^^^^^^^^^^^^^^^^^^^^^^^^^^^^^^^^^^^^^^
  File "C:\Users\RollPy\AppData\Local\pypoetry\Cache\virtualenvs\assistant-SImE5PKe-py3.12\Lib\site-packages\django\template\loader.py", line 62, in render_to_string
    return template.render(context, request)
           ^^^^^^^^^^^^^^^^^^^^^^^^^^^^^^^^^
  File "C:\Users\RollPy\AppData\Local\pypoetry\Cache\virtualenvs\assistant-SImE5PKe-py3.12\Lib\site-packages\django\template\backends\django.py", line 61, in render
    return self.template.render(context)
           ^^^^^^^^^^^^^^^^^^^^^^^^^^^^^
  File "C:\Users\RollPy\AppData\Local\pypoetry\Cache\virtualenvs\assistant-SImE5PKe-py3.12\Lib\site-packages\django\template\base.py", line 171, in render
    return self._render(context)
           ^^^^^^^^^^^^^^^^^^^^^
  File "C:\Users\RollPy\AppData\Local\pypoetry\Cache\virtualenvs\assistant-SImE5PKe-py3.12\Lib\site-packages\django\template\base.py", line 163, in _render
    return self.nodelist.render(context)
           ^^^^^^^^^^^^^^^^^^^^^^^^^^^^^
  File "C:\Users\RollPy\AppData\Local\pypoetry\Cache\virtualenvs\assistant-SImE5PKe-py3.12\Lib\site-packages\django\template\base.py", line 1000, in render
    return SafeString("".join([node.render_annotated(context) for node in self]))
                               ^^^^^^^^^^^^^^^^^^^^^^^^^^^^^^
  File "C:\Users\RollPy\AppData\Local\pypoetry\Cache\virtualenvs\assistant-SImE5PKe-py3.12\Lib\site-packages\django\template\base.py", line 961, in render_annotated
    return self.render(context)
           ^^^^^^^^^^^^^^^^^^^^
  File "C:\Users\RollPy\AppData\Local\pypoetry\Cache\virtualenvs\assistant-SImE5PKe-py3.12\Lib\site-packages\django\template\loader_tags.py", line 56, in render
    result = self.nodelist.render(context)
             ^^^^^^^^^^^^^^^^^^^^^^^^^^^^^
  File "C:\Users\RollPy\AppData\Local\pypoetry\Cache\virtualenvs\assistant-SImE5PKe-py3.12\Lib\site-packages\django\template\base.py", line 1000, in render
    return SafeString("".join([node.render_annotated(context) for node in self]))
                               ^^^^^^^^^^^^^^^^^^^^^^^^^^^^^^
  File "C:\Users\RollPy\AppData\Local\pypoetry\Cache\virtualenvs\assistant-SImE5PKe-py3.12\Lib\site-packages\django\template\base.py", line 961, in render_annotated
    return self.render(context)
           ^^^^^^^^^^^^^^^^^^^^
  File "C:\Users\RollPy\AppData\Local\pypoetry\Cache\virtualenvs\assistant-SImE5PKe-py3.12\Lib\site-packages\django\template\defaulttags.py", line 479, in render
    url = reverse(view_name, args=args, kwargs=kwargs, current_app=current_app)
          ^^^^^^^^^^^^^^^^^^^^^^^^^^^^^^^^^^^^^^^^^^^^^^^^^^^^^^^^^^^^^^^^^^^^^
  File "C:\Users\RollPy\AppData\Local\pypoetry\Cache\virtualenvs\assistant-SImE5PKe-py3.12\Lib\site-packages\django\urls\base.py", line 88, in reverse
    return resolver._reverse_with_prefix(view, prefix, *args, **kwargs)
           ^^^^^^^^^^^^^^^^^^^^^^^^^^^^^^^^^^^^^^^^^^^^^^^^^^^^^^^^^^^^
  File "C:\Users\RollPy\AppData\Local\pypoetry\Cache\virtualenvs\assistant-SImE5PKe-py3.12\Lib\site-packages\django\urls\resolvers.py", line 851, in _reverse_with_prefix
    raise NoReverseMatch(msg)
django.urls.exceptions.NoReverseMatch: Reverse for 'show_images' not found. 'show_images' is not a valid view function or pattern name.
Internal Server Error: /files/listfiles/
Traceback (most recent call last):
  File "C:\Users\RollPy\AppData\Local\pypoetry\Cache\virtualenvs\assistant-SImE5PKe-py3.12\Lib\site-packages\django\core\handlers\exception.py", line 55, in inner
    response = get_response(request)
               ^^^^^^^^^^^^^^^^^^^^^
  File "C:\Users\RollPy\AppData\Local\pypoetry\Cache\virtualenvs\assistant-SImE5PKe-py3.12\Lib\site-packages\django\core\handlers\base.py", line 197, in _get_response
    response = wrapped_callback(request, *callback_args, **callback_kwargs)
               ^^^^^^^^^^^^^^^^^^^^^^^^^^^^^^^^^^^^^^^^^^^^^^^^^^^^^^^^^^^^
  File "C:\Users\RollPy\Documents\GitHub\Django-Personal-Assistant\DPA\files\views.py", line 43, in get_filelist_from_drive
    return render(request, 'files/file_list_using_base.html.html',
           ^^^^^^^^^^^^^^^^^^^^^^^^^^^^^^^^^^^^^^^^^^^^^^^^^^^^^^^
  File "C:\Users\RollPy\AppData\Local\pypoetry\Cache\virtualenvs\assistant-SImE5PKe-py3.12\Lib\site-packages\django\shortcuts.py", line 25, in render
    content = loader.render_to_string(template_name, context, request, using=using)
              ^^^^^^^^^^^^^^^^^^^^^^^^^^^^^^^^^^^^^^^^^^^^^^^^^^^^^^^^^^^^^^^^^^^^^
  File "C:\Users\RollPy\AppData\Local\pypoetry\Cache\virtualenvs\assistant-SImE5PKe-py3.12\Lib\site-packages\django\template\loader.py", line 61, in render_to_string
    template = get_template(template_name, using=using)
               ^^^^^^^^^^^^^^^^^^^^^^^^^^^^^^^^^^^^^^^^
  File "C:\Users\RollPy\AppData\Local\pypoetry\Cache\virtualenvs\assistant-SImE5PKe-py3.12\Lib\site-packages\django\template\loader.py", line 19, in get_template
    raise TemplateDoesNotExist(template_name, chain=chain)
django.template.exceptions.TemplateDoesNotExist: files/file_list_using_base.html.html
Not Found: /favicon.ico
Internal Server Error: /files/images/
Traceback (most recent call last):
  File "C:\Users\RollPy\AppData\Local\pypoetry\Cache\virtualenvs\assistant-SImE5PKe-py3.12\Lib\site-packages\django\core\handlers\exception.py", line 55, in inner
    response = get_response(request)
               ^^^^^^^^^^^^^^^^^^^^^
  File "C:\Users\RollPy\AppData\Local\pypoetry\Cache\virtualenvs\assistant-SImE5PKe-py3.12\Lib\site-packages\django\core\handlers\base.py", line 197, in _get_response
    response = wrapped_callback(request, *callback_args, **callback_kwargs)
               ^^^^^^^^^^^^^^^^^^^^^^^^^^^^^^^^^^^^^^^^^^^^^^^^^^^^^^^^^^^^
  File "C:\Users\RollPy\Documents\GitHub\Django-Personal-Assistant\DPA\files\views.py", line 191, in show_images
    return render(request, 'files/images.html', context={data['images']})
                                                        ^^^^^^^^^^^^^^^^
TypeError: unhashable type: 'dict'
Internal Server Error: /files/images/
Traceback (most recent call last):
  File "C:\Users\RollPy\AppData\Local\pypoetry\Cache\virtualenvs\assistant-SImE5PKe-py3.12\Lib\site-packages\django\core\handlers\exception.py", line 55, in inner
    response = get_response(request)
               ^^^^^^^^^^^^^^^^^^^^^
  File "C:\Users\RollPy\AppData\Local\pypoetry\Cache\virtualenvs\assistant-SImE5PKe-py3.12\Lib\site-packages\django\core\handlers\base.py", line 197, in _get_response
    response = wrapped_callback(request, *callback_args, **callback_kwargs)
               ^^^^^^^^^^^^^^^^^^^^^^^^^^^^^^^^^^^^^^^^^^^^^^^^^^^^^^^^^^^^
  File "C:\Users\RollPy\Documents\GitHub\Django-Personal-Assistant\DPA\files\views.py", line 191, in show_images
    return render(request, 'files/images.html', context={'images': data['images']})
           ^^^^^^^^^^^^^^^^^^^^^^^^^^^^^^^^^^^^^^^^^^^^^^^^^^^^^^^^^^^^^^^^^^^^^^^^
  File "C:\Users\RollPy\AppData\Local\pypoetry\Cache\virtualenvs\assistant-SImE5PKe-py3.12\Lib\site-packages\django\shortcuts.py", line 25, in render
    content = loader.render_to_string(template_name, context, request, using=using)
              ^^^^^^^^^^^^^^^^^^^^^^^^^^^^^^^^^^^^^^^^^^^^^^^^^^^^^^^^^^^^^^^^^^^^^
  File "C:\Users\RollPy\AppData\Local\pypoetry\Cache\virtualenvs\assistant-SImE5PKe-py3.12\Lib\site-packages\django\template\loader.py", line 62, in render_to_string
    return template.render(context, request)
           ^^^^^^^^^^^^^^^^^^^^^^^^^^^^^^^^^
  File "C:\Users\RollPy\AppData\Local\pypoetry\Cache\virtualenvs\assistant-SImE5PKe-py3.12\Lib\site-packages\django\template\backends\django.py", line 61, in render
    return self.template.render(context)
           ^^^^^^^^^^^^^^^^^^^^^^^^^^^^^
  File "C:\Users\RollPy\AppData\Local\pypoetry\Cache\virtualenvs\assistant-SImE5PKe-py3.12\Lib\site-packages\django\template\base.py", line 171, in render
    return self._render(context)
           ^^^^^^^^^^^^^^^^^^^^^
  File "C:\Users\RollPy\AppData\Local\pypoetry\Cache\virtualenvs\assistant-SImE5PKe-py3.12\Lib\site-packages\django\template\base.py", line 163, in _render
    return self.nodelist.render(context)
           ^^^^^^^^^^^^^^^^^^^^^^^^^^^^^
  File "C:\Users\RollPy\AppData\Local\pypoetry\Cache\virtualenvs\assistant-SImE5PKe-py3.12\Lib\site-packages\django\template\base.py", line 1000, in render
    return SafeString("".join([node.render_annotated(context) for node in self]))
                               ^^^^^^^^^^^^^^^^^^^^^^^^^^^^^^
  File "C:\Users\RollPy\AppData\Local\pypoetry\Cache\virtualenvs\assistant-SImE5PKe-py3.12\Lib\site-packages\django\template\base.py", line 961, in render_annotated
    return self.render(context)
           ^^^^^^^^^^^^^^^^^^^^
  File "C:\Users\RollPy\AppData\Local\pypoetry\Cache\virtualenvs\assistant-SImE5PKe-py3.12\Lib\site-packages\django\template\defaulttags.py", line 242, in render
    nodelist.append(node.render_annotated(context))
                    ^^^^^^^^^^^^^^^^^^^^^^^^^^^^^^
  File "C:\Users\RollPy\AppData\Local\pypoetry\Cache\virtualenvs\assistant-SImE5PKe-py3.12\Lib\site-packages\django\template\base.py", line 961, in render_annotated
    return self.render(context)
           ^^^^^^^^^^^^^^^^^^^^
  File "C:\Users\RollPy\AppData\Local\pypoetry\Cache\virtualenvs\assistant-SImE5PKe-py3.12\Lib\site-packages\django\template\defaulttags.py", line 479, in render
    url = reverse(view_name, args=args, kwargs=kwargs, current_app=current_app)
          ^^^^^^^^^^^^^^^^^^^^^^^^^^^^^^^^^^^^^^^^^^^^^^^^^^^^^^^^^^^^^^^^^^^^^
  File "C:\Users\RollPy\AppData\Local\pypoetry\Cache\virtualenvs\assistant-SImE5PKe-py3.12\Lib\site-packages\django\urls\base.py", line 88, in reverse
    return resolver._reverse_with_prefix(view, prefix, *args, **kwargs)
           ^^^^^^^^^^^^^^^^^^^^^^^^^^^^^^^^^^^^^^^^^^^^^^^^^^^^^^^^^^^^
  File "C:\Users\RollPy\AppData\Local\pypoetry\Cache\virtualenvs\assistant-SImE5PKe-py3.12\Lib\site-packages\django\urls\resolvers.py", line 851, in _reverse_with_prefix
    raise NoReverseMatch(msg)
django.urls.exceptions.NoReverseMatch: Reverse for 'delete_contact' with arguments '('',)' not found. 1 pattern(s) tried: ['content/delete_contact/(?P<contact_id>[0-9]+)/\\Z']
Internal Server Error: /files/images/
Traceback (most recent call last):
  File "C:\Users\RollPy\AppData\Local\pypoetry\Cache\virtualenvs\assistant-SImE5PKe-py3.12\Lib\site-packages\django\core\handlers\exception.py", line 55, in inner
    response = get_response(request)
               ^^^^^^^^^^^^^^^^^^^^^
  File "C:\Users\RollPy\AppData\Local\pypoetry\Cache\virtualenvs\assistant-SImE5PKe-py3.12\Lib\site-packages\django\core\handlers\base.py", line 197, in _get_response
    response = wrapped_callback(request, *callback_args, **callback_kwargs)
               ^^^^^^^^^^^^^^^^^^^^^^^^^^^^^^^^^^^^^^^^^^^^^^^^^^^^^^^^^^^^
  File "C:\Users\RollPy\Documents\GitHub\Django-Personal-Assistant\DPA\files\views.py", line 191, in show_images
    return render(request, 'files/images.html', context={'images': data['images']})
           ^^^^^^^^^^^^^^^^^^^^^^^^^^^^^^^^^^^^^^^^^^^^^^^^^^^^^^^^^^^^^^^^^^^^^^^^
  File "C:\Users\RollPy\AppData\Local\pypoetry\Cache\virtualenvs\assistant-SImE5PKe-py3.12\Lib\site-packages\django\shortcuts.py", line 25, in render
    content = loader.render_to_string(template_name, context, request, using=using)
              ^^^^^^^^^^^^^^^^^^^^^^^^^^^^^^^^^^^^^^^^^^^^^^^^^^^^^^^^^^^^^^^^^^^^^
  File "C:\Users\RollPy\AppData\Local\pypoetry\Cache\virtualenvs\assistant-SImE5PKe-py3.12\Lib\site-packages\django\template\loader.py", line 61, in render_to_string
    template = get_template(template_name, using=using)
               ^^^^^^^^^^^^^^^^^^^^^^^^^^^^^^^^^^^^^^^^
  File "C:\Users\RollPy\AppData\Local\pypoetry\Cache\virtualenvs\assistant-SImE5PKe-py3.12\Lib\site-packages\django\template\loader.py", line 15, in get_template
    return engine.get_template(template_name)
           ^^^^^^^^^^^^^^^^^^^^^^^^^^^^^^^^^^
  File "C:\Users\RollPy\AppData\Local\pypoetry\Cache\virtualenvs\assistant-SImE5PKe-py3.12\Lib\site-packages\django\template\backends\django.py", line 33, in get_template
    return Template(self.engine.get_template(template_name), self)
                    ^^^^^^^^^^^^^^^^^^^^^^^^^^^^^^^^^^^^^^^
  File "C:\Users\RollPy\AppData\Local\pypoetry\Cache\virtualenvs\assistant-SImE5PKe-py3.12\Lib\site-packages\django\template\engine.py", line 177, in get_template
    template, origin = self.find_template(template_name)
                       ^^^^^^^^^^^^^^^^^^^^^^^^^^^^^^^^^
  File "C:\Users\RollPy\AppData\Local\pypoetry\Cache\virtualenvs\assistant-SImE5PKe-py3.12\Lib\site-packages\django\template\engine.py", line 159, in find_template
    template = loader.get_template(name, skip=skip)
               ^^^^^^^^^^^^^^^^^^^^^^^^^^^^^^^^^^^^
  File "C:\Users\RollPy\AppData\Local\pypoetry\Cache\virtualenvs\assistant-SImE5PKe-py3.12\Lib\site-packages\django\template\loaders\cached.py", line 57, in get_template
    template = super().get_template(template_name, skip)
               ^^^^^^^^^^^^^^^^^^^^^^^^^^^^^^^^^^^^^^^^^
  File "C:\Users\RollPy\AppData\Local\pypoetry\Cache\virtualenvs\assistant-SImE5PKe-py3.12\Lib\site-packages\django\template\loaders\base.py", line 28, in get_template
    return Template(
           ^^^^^^^^^
  File "C:\Users\RollPy\AppData\Local\pypoetry\Cache\virtualenvs\assistant-SImE5PKe-py3.12\Lib\site-packages\django\template\base.py", line 154, in __init__
    self.nodelist = self.compile_nodelist()
                    ^^^^^^^^^^^^^^^^^^^^^^^
  File "C:\Users\RollPy\AppData\Local\pypoetry\Cache\virtualenvs\assistant-SImE5PKe-py3.12\Lib\site-packages\django\template\base.py", line 196, in compile_nodelist
    return parser.parse()
           ^^^^^^^^^^^^^^
  File "C:\Users\RollPy\AppData\Local\pypoetry\Cache\virtualenvs\assistant-SImE5PKe-py3.12\Lib\site-packages\django\template\base.py", line 510, in parse
    raise self.error(token, e)
  File "C:\Users\RollPy\AppData\Local\pypoetry\Cache\virtualenvs\assistant-SImE5PKe-py3.12\Lib\site-packages\django\template\base.py", line 508, in parse
    compiled_result = compile_func(self, token)
                      ^^^^^^^^^^^^^^^^^^^^^^^^^
  File "C:\Users\RollPy\AppData\Local\pypoetry\Cache\virtualenvs\assistant-SImE5PKe-py3.12\Lib\site-packages\django\template\defaulttags.py", line 861, in do_for
    nodelist_loop = parser.parse(
                    ^^^^^^^^^^^^^
  File "C:\Users\RollPy\AppData\Local\pypoetry\Cache\virtualenvs\assistant-SImE5PKe-py3.12\Lib\site-packages\django\template\base.py", line 510, in parse
    raise self.error(token, e)
  File "C:\Users\RollPy\AppData\Local\pypoetry\Cache\virtualenvs\assistant-SImE5PKe-py3.12\Lib\site-packages\django\template\base.py", line 508, in parse
    compiled_result = compile_func(self, token)
                      ^^^^^^^^^^^^^^^^^^^^^^^^^
  File "C:\Users\RollPy\AppData\Local\pypoetry\Cache\virtualenvs\assistant-SImE5PKe-py3.12\Lib\site-packages\django\template\defaulttags.py", line 1380, in url
    viewname = parser.compile_filter(bits[1])
               ^^^^^^^^^^^^^^^^^^^^^^^^^^^^^^
  File "C:\Users\RollPy\AppData\Local\pypoetry\Cache\virtualenvs\assistant-SImE5PKe-py3.12\Lib\site-packages\django\template\base.py", line 597, in compile_filter
    return FilterExpression(token, self)
           ^^^^^^^^^^^^^^^^^^^^^^^^^^^^^
  File "C:\Users\RollPy\AppData\Local\pypoetry\Cache\virtualenvs\assistant-SImE5PKe-py3.12\Lib\site-packages\django\template\base.py", line 698, in __init__
    raise TemplateSyntaxError(
django.template.exceptions.TemplateSyntaxError: Could not parse the remainder: 'id' from ''files:delete_file'id'
Internal Server Error: /files/delete/1o3LA-QGCGBrA6pDQEz5yIfHTeOnrE_za
Traceback (most recent call last):
  File "C:\Users\RollPy\AppData\Local\pypoetry\Cache\virtualenvs\assistant-SImE5PKe-py3.12\Lib\site-packages\django\core\handlers\exception.py", line 55, in inner
    response = get_response(request)
               ^^^^^^^^^^^^^^^^^^^^^
  File "C:\Users\RollPy\AppData\Local\pypoetry\Cache\virtualenvs\assistant-SImE5PKe-py3.12\Lib\site-packages\django\core\handlers\base.py", line 197, in _get_response
    response = wrapped_callback(request, *callback_args, **callback_kwargs)
               ^^^^^^^^^^^^^^^^^^^^^^^^^^^^^^^^^^^^^^^^^^^^^^^^^^^^^^^^^^^^
  File "C:\Users\RollPy\AppData\Local\pypoetry\Cache\virtualenvs\assistant-SImE5PKe-py3.12\Lib\site-packages\asgiref\sync.py", line 254, in __call__
    return call_result.result()
           ^^^^^^^^^^^^^^^^^^^^
  File "C:\Users\RollPy\AppData\Local\Programs\Python\Python312\Lib\concurrent\futures\_base.py", line 449, in result
    return self.__get_result()
           ^^^^^^^^^^^^^^^^^^^
  File "C:\Users\RollPy\AppData\Local\Programs\Python\Python312\Lib\concurrent\futures\_base.py", line 401, in __get_result
    raise self._exception
  File "C:\Users\RollPy\AppData\Local\pypoetry\Cache\virtualenvs\assistant-SImE5PKe-py3.12\Lib\site-packages\asgiref\sync.py", line 331, in main_wrap
    result = await self.awaitable(*args, **kwargs)
             ^^^^^^^^^^^^^^^^^^^^^^^^^^^^^^^^^^^^^
  File "C:\Users\RollPy\Documents\GitHub\Django-Personal-Assistant\DPA\files\views.py", line 182, in delete_file
    await aiogoogle.as_user(
  File "C:\Users\RollPy\AppData\Local\pypoetry\Cache\virtualenvs\assistant-SImE5PKe-py3.12\Lib\site-packages\aiogoogle\client.py", line 254, in as_user
    return await self.send(
           ^^^^^^^^^^^^^^^^
  File "C:\Users\RollPy\AppData\Local\pypoetry\Cache\virtualenvs\assistant-SImE5PKe-py3.12\Lib\site-packages\aiogoogle\client.py", line 409, in send
    return await session.send(*args, **kwargs)
           ^^^^^^^^^^^^^^^^^^^^^^^^^^^^^^^^^^^
  File "C:\Users\RollPy\AppData\Local\pypoetry\Cache\virtualenvs\assistant-SImE5PKe-py3.12\Lib\site-packages\aiogoogle\sessions\aiohttp_session.py", line 186, in send
    results = await schedule_tasks()
              ^^^^^^^^^^^^^^^^^^^^^^
  File "C:\Users\RollPy\AppData\Local\pypoetry\Cache\virtualenvs\assistant-SImE5PKe-py3.12\Lib\site-packages\aiogoogle\sessions\aiohttp_session.py", line 171, in schedule_tasks
    return await asyncio.gather(
           ^^^^^^^^^^^^^^^^^^^^^
  File "C:\Users\RollPy\AppData\Local\pypoetry\Cache\virtualenvs\assistant-SImE5PKe-py3.12\Lib\site-packages\aiogoogle\sessions\aiohttp_session.py", line 165, in get_content
    response = await get_response(request)
               ^^^^^^^^^^^^^^^^^^^^^^^^^^^
  File "C:\Users\RollPy\AppData\Local\pypoetry\Cache\virtualenvs\assistant-SImE5PKe-py3.12\Lib\site-packages\aiogoogle\sessions\aiohttp_session.py", line 161, in get_response
    response.raise_for_status()
  File "C:\Users\RollPy\AppData\Local\pypoetry\Cache\virtualenvs\assistant-SImE5PKe-py3.12\Lib\site-packages\aiogoogle\models.py", line 480, in raise_for_status
    raise HTTPError(msg=self.reason, req=self.req, res=self)
aiogoogle.excs.HTTPError: 



Not Found

Content:
{'code': 404,
 'errors': [{'domain': 'global',
             'location': 'fileId',
             'locationType': 'parameter',
             'message': 'File not found: 1o3LA-QGCGBrA6pDQEz5yIfHTeOnrE_za.',
             'reason': 'notFound'}],
 'message': 'File not found: 1o3LA-QGCGBrA6pDQEz5yIfHTeOnrE_za.'}

Request URL:
https://www.googleapis.com/drive/v3/files/1o3LA-QGCGBrA6pDQEz5yIfHTeOnrE_za
Internal Server Error: /files/delete/1o3LA-QGCGBrA6pDQEz5yIfHTeOnrE_za
Traceback (most recent call last):
  File "C:\Users\RollPy\AppData\Local\pypoetry\Cache\virtualenvs\assistant-SImE5PKe-py3.12\Lib\site-packages\django\core\handlers\exception.py", line 55, in inner
    response = get_response(request)
               ^^^^^^^^^^^^^^^^^^^^^
  File "C:\Users\RollPy\AppData\Local\pypoetry\Cache\virtualenvs\assistant-SImE5PKe-py3.12\Lib\site-packages\django\core\handlers\base.py", line 197, in _get_response
    response = wrapped_callback(request, *callback_args, **callback_kwargs)
               ^^^^^^^^^^^^^^^^^^^^^^^^^^^^^^^^^^^^^^^^^^^^^^^^^^^^^^^^^^^^
  File "C:\Users\RollPy\AppData\Local\pypoetry\Cache\virtualenvs\assistant-SImE5PKe-py3.12\Lib\site-packages\asgiref\sync.py", line 254, in __call__
    return call_result.result()
           ^^^^^^^^^^^^^^^^^^^^
  File "C:\Users\RollPy\AppData\Local\Programs\Python\Python312\Lib\concurrent\futures\_base.py", line 449, in result
    return self.__get_result()
           ^^^^^^^^^^^^^^^^^^^
  File "C:\Users\RollPy\AppData\Local\Programs\Python\Python312\Lib\concurrent\futures\_base.py", line 401, in __get_result
    raise self._exception
  File "C:\Users\RollPy\AppData\Local\pypoetry\Cache\virtualenvs\assistant-SImE5PKe-py3.12\Lib\site-packages\asgiref\sync.py", line 331, in main_wrap
    result = await self.awaitable(*args, **kwargs)
             ^^^^^^^^^^^^^^^^^^^^^^^^^^^^^^^^^^^^^
  File "C:\Users\RollPy\Documents\GitHub\Django-Personal-Assistant\DPA\files\views.py", line 182, in delete_file
    await aiogoogle.as_user(
  File "C:\Users\RollPy\AppData\Local\pypoetry\Cache\virtualenvs\assistant-SImE5PKe-py3.12\Lib\site-packages\aiogoogle\client.py", line 254, in as_user
    return await self.send(
           ^^^^^^^^^^^^^^^^
  File "C:\Users\RollPy\AppData\Local\pypoetry\Cache\virtualenvs\assistant-SImE5PKe-py3.12\Lib\site-packages\aiogoogle\client.py", line 409, in send
    return await session.send(*args, **kwargs)
           ^^^^^^^^^^^^^^^^^^^^^^^^^^^^^^^^^^^
  File "C:\Users\RollPy\AppData\Local\pypoetry\Cache\virtualenvs\assistant-SImE5PKe-py3.12\Lib\site-packages\aiogoogle\sessions\aiohttp_session.py", line 186, in send
    results = await schedule_tasks()
              ^^^^^^^^^^^^^^^^^^^^^^
  File "C:\Users\RollPy\AppData\Local\pypoetry\Cache\virtualenvs\assistant-SImE5PKe-py3.12\Lib\site-packages\aiogoogle\sessions\aiohttp_session.py", line 171, in schedule_tasks
    return await asyncio.gather(
           ^^^^^^^^^^^^^^^^^^^^^
  File "C:\Users\RollPy\AppData\Local\pypoetry\Cache\virtualenvs\assistant-SImE5PKe-py3.12\Lib\site-packages\aiogoogle\sessions\aiohttp_session.py", line 165, in get_content
    response = await get_response(request)
               ^^^^^^^^^^^^^^^^^^^^^^^^^^^
  File "C:\Users\RollPy\AppData\Local\pypoetry\Cache\virtualenvs\assistant-SImE5PKe-py3.12\Lib\site-packages\aiogoogle\sessions\aiohttp_session.py", line 161, in get_response
    response.raise_for_status()
  File "C:\Users\RollPy\AppData\Local\pypoetry\Cache\virtualenvs\assistant-SImE5PKe-py3.12\Lib\site-packages\aiogoogle\models.py", line 480, in raise_for_status
    raise HTTPError(msg=self.reason, req=self.req, res=self)
aiogoogle.excs.HTTPError: 



Not Found

Content:
{'code': 404,
 'errors': [{'domain': 'global',
             'location': 'fileId',
             'locationType': 'parameter',
             'message': 'File not found: 1o3LA-QGCGBrA6pDQEz5yIfHTeOnrE_za.',
             'reason': 'notFound'}],
 'message': 'File not found: 1o3LA-QGCGBrA6pDQEz5yIfHTeOnrE_za.'}

Request URL:
https://www.googleapis.com/drive/v3/files/1o3LA-QGCGBrA6pDQEz5yIfHTeOnrE_za
Internal Server Error: /files/listfiles/
Traceback (most recent call last):
  File "C:\Users\RollPy\AppData\Local\pypoetry\Cache\virtualenvs\assistant-SImE5PKe-py3.12\Lib\site-packages\django\core\handlers\exception.py", line 55, in inner
    response = get_response(request)
               ^^^^^^^^^^^^^^^^^^^^^
  File "C:\Users\RollPy\AppData\Local\pypoetry\Cache\virtualenvs\assistant-SImE5PKe-py3.12\Lib\site-packages\django\core\handlers\base.py", line 197, in _get_response
    response = wrapped_callback(request, *callback_args, **callback_kwargs)
               ^^^^^^^^^^^^^^^^^^^^^^^^^^^^^^^^^^^^^^^^^^^^^^^^^^^^^^^^^^^^
  File "C:\Users\RollPy\Documents\GitHub\Django-Personal-Assistant\DPA\files\views.py", line 43, in get_filelist_from_drive
    return render(request, 'files/async_show_files_list.html.html',
           ^^^^^^^^^^^^^^^^^^^^^^^^^^^^^^^^^^^^^^^^^^^^^^^^^^^^^^^^
  File "C:\Users\RollPy\AppData\Local\pypoetry\Cache\virtualenvs\assistant-SImE5PKe-py3.12\Lib\site-packages\django\shortcuts.py", line 25, in render
    content = loader.render_to_string(template_name, context, request, using=using)
              ^^^^^^^^^^^^^^^^^^^^^^^^^^^^^^^^^^^^^^^^^^^^^^^^^^^^^^^^^^^^^^^^^^^^^
  File "C:\Users\RollPy\AppData\Local\pypoetry\Cache\virtualenvs\assistant-SImE5PKe-py3.12\Lib\site-packages\django\template\loader.py", line 61, in render_to_string
    template = get_template(template_name, using=using)
               ^^^^^^^^^^^^^^^^^^^^^^^^^^^^^^^^^^^^^^^^
  File "C:\Users\RollPy\AppData\Local\pypoetry\Cache\virtualenvs\assistant-SImE5PKe-py3.12\Lib\site-packages\django\template\loader.py", line 19, in get_template
    raise TemplateDoesNotExist(template_name, chain=chain)
django.template.exceptions.TemplateDoesNotExist: files/async_show_files_list.html.html
Internal Server Error: /files/delete/1Z2Dqaj6KdnV3964HvMhWltTqF3FhloSm
Traceback (most recent call last):
  File "C:\Users\RollPy\AppData\Local\pypoetry\Cache\virtualenvs\assistant-SImE5PKe-py3.12\Lib\site-packages\django\core\handlers\exception.py", line 55, in inner
    response = get_response(request)
               ^^^^^^^^^^^^^^^^^^^^^
  File "C:\Users\RollPy\AppData\Local\pypoetry\Cache\virtualenvs\assistant-SImE5PKe-py3.12\Lib\site-packages\django\core\handlers\base.py", line 197, in _get_response
    response = wrapped_callback(request, *callback_args, **callback_kwargs)
               ^^^^^^^^^^^^^^^^^^^^^^^^^^^^^^^^^^^^^^^^^^^^^^^^^^^^^^^^^^^^
  File "C:\Users\RollPy\AppData\Local\pypoetry\Cache\virtualenvs\assistant-SImE5PKe-py3.12\Lib\site-packages\asgiref\sync.py", line 254, in __call__
    return call_result.result()
           ^^^^^^^^^^^^^^^^^^^^
  File "C:\Users\RollPy\AppData\Local\Programs\Python\Python312\Lib\concurrent\futures\_base.py", line 449, in result
    return self.__get_result()
           ^^^^^^^^^^^^^^^^^^^
  File "C:\Users\RollPy\AppData\Local\Programs\Python\Python312\Lib\concurrent\futures\_base.py", line 401, in __get_result
    raise self._exception
  File "C:\Users\RollPy\AppData\Local\pypoetry\Cache\virtualenvs\assistant-SImE5PKe-py3.12\Lib\site-packages\asgiref\sync.py", line 331, in main_wrap
    result = await self.awaitable(*args, **kwargs)
             ^^^^^^^^^^^^^^^^^^^^^^^^^^^^^^^^^^^^^
  File "C:\Users\RollPy\Documents\GitHub\Django-Personal-Assistant\DPA\files\views.py", line 182, in delete_file
    await aiogoogle.as_user(
  File "C:\Users\RollPy\AppData\Local\pypoetry\Cache\virtualenvs\assistant-SImE5PKe-py3.12\Lib\site-packages\aiogoogle\client.py", line 254, in as_user
    return await self.send(
           ^^^^^^^^^^^^^^^^
  File "C:\Users\RollPy\AppData\Local\pypoetry\Cache\virtualenvs\assistant-SImE5PKe-py3.12\Lib\site-packages\aiogoogle\client.py", line 409, in send
    return await session.send(*args, **kwargs)
           ^^^^^^^^^^^^^^^^^^^^^^^^^^^^^^^^^^^
  File "C:\Users\RollPy\AppData\Local\pypoetry\Cache\virtualenvs\assistant-SImE5PKe-py3.12\Lib\site-packages\aiogoogle\sessions\aiohttp_session.py", line 186, in send
    results = await schedule_tasks()
              ^^^^^^^^^^^^^^^^^^^^^^
  File "C:\Users\RollPy\AppData\Local\pypoetry\Cache\virtualenvs\assistant-SImE5PKe-py3.12\Lib\site-packages\aiogoogle\sessions\aiohttp_session.py", line 171, in schedule_tasks
    return await asyncio.gather(
           ^^^^^^^^^^^^^^^^^^^^^
  File "C:\Users\RollPy\AppData\Local\pypoetry\Cache\virtualenvs\assistant-SImE5PKe-py3.12\Lib\site-packages\aiogoogle\sessions\aiohttp_session.py", line 165, in get_content
    response = await get_response(request)
               ^^^^^^^^^^^^^^^^^^^^^^^^^^^
  File "C:\Users\RollPy\AppData\Local\pypoetry\Cache\virtualenvs\assistant-SImE5PKe-py3.12\Lib\site-packages\aiogoogle\sessions\aiohttp_session.py", line 161, in get_response
    response.raise_for_status()
  File "C:\Users\RollPy\AppData\Local\pypoetry\Cache\virtualenvs\assistant-SImE5PKe-py3.12\Lib\site-packages\aiogoogle\models.py", line 480, in raise_for_status
    raise HTTPError(msg=self.reason, req=self.req, res=self)
aiogoogle.excs.HTTPError: 



Not Found

Content:
{'code': 404,
 'errors': [{'domain': 'global',
             'location': 'fileId',
             'locationType': 'parameter',
             'message': 'File not found: 1Z2Dqaj6KdnV3964HvMhWltTqF3FhloSm.',
             'reason': 'notFound'}],
 'message': 'File not found: 1Z2Dqaj6KdnV3964HvMhWltTqF3FhloSm.'}

Request URL:
https://www.googleapis.com/drive/v3/files/1Z2Dqaj6KdnV3964HvMhWltTqF3FhloSm
Internal Server Error: /files/delete/1texpj3gRmSMTAZ8GVNljKa3B_IPSqH1n
Traceback (most recent call last):
  File "C:\Users\RollPy\AppData\Local\pypoetry\Cache\virtualenvs\assistant-SImE5PKe-py3.12\Lib\site-packages\django\core\handlers\exception.py", line 55, in inner
    response = get_response(request)
               ^^^^^^^^^^^^^^^^^^^^^
  File "C:\Users\RollPy\AppData\Local\pypoetry\Cache\virtualenvs\assistant-SImE5PKe-py3.12\Lib\site-packages\django\core\handlers\base.py", line 197, in _get_response
    response = wrapped_callback(request, *callback_args, **callback_kwargs)
               ^^^^^^^^^^^^^^^^^^^^^^^^^^^^^^^^^^^^^^^^^^^^^^^^^^^^^^^^^^^^
  File "C:\Users\RollPy\AppData\Local\pypoetry\Cache\virtualenvs\assistant-SImE5PKe-py3.12\Lib\site-packages\asgiref\sync.py", line 254, in __call__
    return call_result.result()
           ^^^^^^^^^^^^^^^^^^^^
  File "C:\Users\RollPy\AppData\Local\Programs\Python\Python312\Lib\concurrent\futures\_base.py", line 449, in result
    return self.__get_result()
           ^^^^^^^^^^^^^^^^^^^
  File "C:\Users\RollPy\AppData\Local\Programs\Python\Python312\Lib\concurrent\futures\_base.py", line 401, in __get_result
    raise self._exception
  File "C:\Users\RollPy\AppData\Local\pypoetry\Cache\virtualenvs\assistant-SImE5PKe-py3.12\Lib\site-packages\asgiref\sync.py", line 331, in main_wrap
    result = await self.awaitable(*args, **kwargs)
             ^^^^^^^^^^^^^^^^^^^^^^^^^^^^^^^^^^^^^
  File "C:\Users\RollPy\Documents\GitHub\Django-Personal-Assistant\DPA\files\views.py", line 185, in delete_file
    get_cache_data(request)
  File "C:\Users\RollPy\Documents\GitHub\Django-Personal-Assistant\DPA\files\views.py", line 21, in get_cache_data
    data = async_to_sync(get_file_list_from_drive)(get_folder_id_by_user(request.user))
                                                   ^^^^^^^^^^^^^^^^^^^^^^^^^^^^^^^^^^^
  File "C:\Users\RollPy\Documents\GitHub\Django-Personal-Assistant\DPA\files\views.py", line 27, in get_folder_id_by_user
    with transaction.atomic():
  File "C:\Users\RollPy\AppData\Local\pypoetry\Cache\virtualenvs\assistant-SImE5PKe-py3.12\Lib\site-packages\django\db\transaction.py", line 198, in __enter__
    if not connection.get_autocommit():
           ^^^^^^^^^^^^^^^^^^^^^^^^^^^
  File "C:\Users\RollPy\AppData\Local\pypoetry\Cache\virtualenvs\assistant-SImE5PKe-py3.12\Lib\site-packages\django\db\backends\base\base.py", line 450, in get_autocommit
    self.ensure_connection()
  File "C:\Users\RollPy\AppData\Local\pypoetry\Cache\virtualenvs\assistant-SImE5PKe-py3.12\Lib\site-packages\django\utils\asyncio.py", line 24, in inner
    raise SynchronousOnlyOperation(message)
django.core.exceptions.SynchronousOnlyOperation: You cannot call this from an async context - use a thread or sync_to_async.
Internal Server Error: /files/delete/1texpj3gRmSMTAZ8GVNljKa3B_IPSqH1n
Traceback (most recent call last):
  File "C:\Users\RollPy\AppData\Local\pypoetry\Cache\virtualenvs\assistant-SImE5PKe-py3.12\Lib\site-packages\django\core\handlers\exception.py", line 55, in inner
    response = get_response(request)
               ^^^^^^^^^^^^^^^^^^^^^
  File "C:\Users\RollPy\AppData\Local\pypoetry\Cache\virtualenvs\assistant-SImE5PKe-py3.12\Lib\site-packages\django\core\handlers\base.py", line 197, in _get_response
    response = wrapped_callback(request, *callback_args, **callback_kwargs)
               ^^^^^^^^^^^^^^^^^^^^^^^^^^^^^^^^^^^^^^^^^^^^^^^^^^^^^^^^^^^^
  File "C:\Users\RollPy\AppData\Local\pypoetry\Cache\virtualenvs\assistant-SImE5PKe-py3.12\Lib\site-packages\asgiref\sync.py", line 254, in __call__
    return call_result.result()
           ^^^^^^^^^^^^^^^^^^^^
  File "C:\Users\RollPy\AppData\Local\Programs\Python\Python312\Lib\concurrent\futures\_base.py", line 449, in result
    return self.__get_result()
           ^^^^^^^^^^^^^^^^^^^
  File "C:\Users\RollPy\AppData\Local\Programs\Python\Python312\Lib\concurrent\futures\_base.py", line 401, in __get_result
    raise self._exception
  File "C:\Users\RollPy\AppData\Local\pypoetry\Cache\virtualenvs\assistant-SImE5PKe-py3.12\Lib\site-packages\asgiref\sync.py", line 331, in main_wrap
    result = await self.awaitable(*args, **kwargs)
             ^^^^^^^^^^^^^^^^^^^^^^^^^^^^^^^^^^^^^
  File "C:\Users\RollPy\Documents\GitHub\Django-Personal-Assistant\DPA\files\views.py", line 181, in delete_file
    await aiogoogle.as_user(
  File "C:\Users\RollPy\AppData\Local\pypoetry\Cache\virtualenvs\assistant-SImE5PKe-py3.12\Lib\site-packages\aiogoogle\client.py", line 254, in as_user
    return await self.send(
           ^^^^^^^^^^^^^^^^
  File "C:\Users\RollPy\AppData\Local\pypoetry\Cache\virtualenvs\assistant-SImE5PKe-py3.12\Lib\site-packages\aiogoogle\client.py", line 409, in send
    return await session.send(*args, **kwargs)
           ^^^^^^^^^^^^^^^^^^^^^^^^^^^^^^^^^^^
  File "C:\Users\RollPy\AppData\Local\pypoetry\Cache\virtualenvs\assistant-SImE5PKe-py3.12\Lib\site-packages\aiogoogle\sessions\aiohttp_session.py", line 186, in send
    results = await schedule_tasks()
              ^^^^^^^^^^^^^^^^^^^^^^
  File "C:\Users\RollPy\AppData\Local\pypoetry\Cache\virtualenvs\assistant-SImE5PKe-py3.12\Lib\site-packages\aiogoogle\sessions\aiohttp_session.py", line 171, in schedule_tasks
    return await asyncio.gather(
           ^^^^^^^^^^^^^^^^^^^^^
  File "C:\Users\RollPy\AppData\Local\pypoetry\Cache\virtualenvs\assistant-SImE5PKe-py3.12\Lib\site-packages\aiogoogle\sessions\aiohttp_session.py", line 165, in get_content
    response = await get_response(request)
               ^^^^^^^^^^^^^^^^^^^^^^^^^^^
  File "C:\Users\RollPy\AppData\Local\pypoetry\Cache\virtualenvs\assistant-SImE5PKe-py3.12\Lib\site-packages\aiogoogle\sessions\aiohttp_session.py", line 161, in get_response
    response.raise_for_status()
  File "C:\Users\RollPy\AppData\Local\pypoetry\Cache\virtualenvs\assistant-SImE5PKe-py3.12\Lib\site-packages\aiogoogle\models.py", line 480, in raise_for_status
    raise HTTPError(msg=self.reason, req=self.req, res=self)
aiogoogle.excs.HTTPError: 



Not Found

Content:
{'code': 404,
 'errors': [{'domain': 'global',
             'location': 'fileId',
             'locationType': 'parameter',
             'message': 'File not found: 1texpj3gRmSMTAZ8GVNljKa3B_IPSqH1n.',
             'reason': 'notFound'}],
 'message': 'File not found: 1texpj3gRmSMTAZ8GVNljKa3B_IPSqH1n.'}

Request URL:
https://www.googleapis.com/drive/v3/files/1texpj3gRmSMTAZ8GVNljKa3B_IPSqH1n
Internal Server Error: /files/delete/1L1IYdXXYxp1xiwoX-1LPCYtGp2x_Li1-
Traceback (most recent call last):
  File "C:\Users\RollPy\AppData\Local\pypoetry\Cache\virtualenvs\assistant-SImE5PKe-py3.12\Lib\site-packages\django\core\handlers\exception.py", line 55, in inner
    response = get_response(request)
               ^^^^^^^^^^^^^^^^^^^^^
  File "C:\Users\RollPy\AppData\Local\pypoetry\Cache\virtualenvs\assistant-SImE5PKe-py3.12\Lib\site-packages\django\core\handlers\base.py", line 197, in _get_response
    response = wrapped_callback(request, *callback_args, **callback_kwargs)
               ^^^^^^^^^^^^^^^^^^^^^^^^^^^^^^^^^^^^^^^^^^^^^^^^^^^^^^^^^^^^
  File "C:\Users\RollPy\AppData\Local\pypoetry\Cache\virtualenvs\assistant-SImE5PKe-py3.12\Lib\site-packages\asgiref\sync.py", line 254, in __call__
    return call_result.result()
           ^^^^^^^^^^^^^^^^^^^^
  File "C:\Users\RollPy\AppData\Local\Programs\Python\Python312\Lib\concurrent\futures\_base.py", line 449, in result
    return self.__get_result()
           ^^^^^^^^^^^^^^^^^^^
  File "C:\Users\RollPy\AppData\Local\Programs\Python\Python312\Lib\concurrent\futures\_base.py", line 401, in __get_result
    raise self._exception
  File "C:\Users\RollPy\AppData\Local\pypoetry\Cache\virtualenvs\assistant-SImE5PKe-py3.12\Lib\site-packages\asgiref\sync.py", line 331, in main_wrap
    result = await self.awaitable(*args, **kwargs)
             ^^^^^^^^^^^^^^^^^^^^^^^^^^^^^^^^^^^^^
  File "C:\Users\RollPy\Documents\GitHub\Django-Personal-Assistant\DPA\files\views.py", line 184, in delete_file
    get_cache_data(request)
  File "C:\Users\RollPy\Documents\GitHub\Django-Personal-Assistant\DPA\files\views.py", line 20, in get_cache_data
    data = async_to_sync(get_file_list_from_drive)(get_folder_id_by_user(request.user))
                                                   ^^^^^^^^^^^^^^^^^^^^^^^^^^^^^^^^^^^
  File "C:\Users\RollPy\Documents\GitHub\Django-Personal-Assistant\DPA\files\views.py", line 26, in get_folder_id_by_user
    with transaction.atomic():
  File "C:\Users\RollPy\AppData\Local\pypoetry\Cache\virtualenvs\assistant-SImE5PKe-py3.12\Lib\site-packages\django\db\transaction.py", line 198, in __enter__
    if not connection.get_autocommit():
           ^^^^^^^^^^^^^^^^^^^^^^^^^^^
  File "C:\Users\RollPy\AppData\Local\pypoetry\Cache\virtualenvs\assistant-SImE5PKe-py3.12\Lib\site-packages\django\db\backends\base\base.py", line 450, in get_autocommit
    self.ensure_connection()
  File "C:\Users\RollPy\AppData\Local\pypoetry\Cache\virtualenvs\assistant-SImE5PKe-py3.12\Lib\site-packages\django\utils\asyncio.py", line 24, in inner
    raise SynchronousOnlyOperation(message)
django.core.exceptions.SynchronousOnlyOperation: You cannot call this from an async context - use a thread or sync_to_async.
Internal Server Error: /files/listfiles/
Traceback (most recent call last):
  File "C:\Users\RollPy\AppData\Local\pypoetry\Cache\virtualenvs\assistant-SImE5PKe-py3.12\Lib\site-packages\django\core\handlers\exception.py", line 55, in inner
    response = get_response(request)
               ^^^^^^^^^^^^^^^^^^^^^
  File "C:\Users\RollPy\AppData\Local\pypoetry\Cache\virtualenvs\assistant-SImE5PKe-py3.12\Lib\site-packages\django\core\handlers\base.py", line 197, in _get_response
    response = wrapped_callback(request, *callback_args, **callback_kwargs)
               ^^^^^^^^^^^^^^^^^^^^^^^^^^^^^^^^^^^^^^^^^^^^^^^^^^^^^^^^^^^^
  File "C:\Users\RollPy\Documents\GitHub\Django-Personal-Assistant\DPA\files\views.py", line 46, in get_filelist_from_drive
    return render(request, 'files/async_show_files_list.html',
           ^^^^^^^^^^^^^^^^^^^^^^^^^^^^^^^^^^^^^^^^^^^^^^^^^^^
  File "C:\Users\RollPy\AppData\Local\pypoetry\Cache\virtualenvs\assistant-SImE5PKe-py3.12\Lib\site-packages\django\shortcuts.py", line 25, in render
    content = loader.render_to_string(template_name, context, request, using=using)
              ^^^^^^^^^^^^^^^^^^^^^^^^^^^^^^^^^^^^^^^^^^^^^^^^^^^^^^^^^^^^^^^^^^^^^
  File "C:\Users\RollPy\AppData\Local\pypoetry\Cache\virtualenvs\assistant-SImE5PKe-py3.12\Lib\site-packages\django\template\loader.py", line 61, in render_to_string
    template = get_template(template_name, using=using)
               ^^^^^^^^^^^^^^^^^^^^^^^^^^^^^^^^^^^^^^^^
  File "C:\Users\RollPy\AppData\Local\pypoetry\Cache\virtualenvs\assistant-SImE5PKe-py3.12\Lib\site-packages\django\template\loader.py", line 15, in get_template
    return engine.get_template(template_name)
           ^^^^^^^^^^^^^^^^^^^^^^^^^^^^^^^^^^
  File "C:\Users\RollPy\AppData\Local\pypoetry\Cache\virtualenvs\assistant-SImE5PKe-py3.12\Lib\site-packages\django\template\backends\django.py", line 33, in get_template
    return Template(self.engine.get_template(template_name), self)
                    ^^^^^^^^^^^^^^^^^^^^^^^^^^^^^^^^^^^^^^^
  File "C:\Users\RollPy\AppData\Local\pypoetry\Cache\virtualenvs\assistant-SImE5PKe-py3.12\Lib\site-packages\django\template\engine.py", line 177, in get_template
    template, origin = self.find_template(template_name)
                       ^^^^^^^^^^^^^^^^^^^^^^^^^^^^^^^^^
  File "C:\Users\RollPy\AppData\Local\pypoetry\Cache\virtualenvs\assistant-SImE5PKe-py3.12\Lib\site-packages\django\template\engine.py", line 159, in find_template
    template = loader.get_template(name, skip=skip)
               ^^^^^^^^^^^^^^^^^^^^^^^^^^^^^^^^^^^^
  File "C:\Users\RollPy\AppData\Local\pypoetry\Cache\virtualenvs\assistant-SImE5PKe-py3.12\Lib\site-packages\django\template\loaders\cached.py", line 57, in get_template
    template = super().get_template(template_name, skip)
               ^^^^^^^^^^^^^^^^^^^^^^^^^^^^^^^^^^^^^^^^^
  File "C:\Users\RollPy\AppData\Local\pypoetry\Cache\virtualenvs\assistant-SImE5PKe-py3.12\Lib\site-packages\django\template\loaders\base.py", line 28, in get_template
    return Template(
           ^^^^^^^^^
  File "C:\Users\RollPy\AppData\Local\pypoetry\Cache\virtualenvs\assistant-SImE5PKe-py3.12\Lib\site-packages\django\template\base.py", line 154, in __init__
    self.nodelist = self.compile_nodelist()
                    ^^^^^^^^^^^^^^^^^^^^^^^
  File "C:\Users\RollPy\AppData\Local\pypoetry\Cache\virtualenvs\assistant-SImE5PKe-py3.12\Lib\site-packages\django\template\base.py", line 196, in compile_nodelist
    return parser.parse()
           ^^^^^^^^^^^^^^
  File "C:\Users\RollPy\AppData\Local\pypoetry\Cache\virtualenvs\assistant-SImE5PKe-py3.12\Lib\site-packages\django\template\base.py", line 510, in parse
    raise self.error(token, e)
  File "C:\Users\RollPy\AppData\Local\pypoetry\Cache\virtualenvs\assistant-SImE5PKe-py3.12\Lib\site-packages\django\template\base.py", line 508, in parse
    compiled_result = compile_func(self, token)
                      ^^^^^^^^^^^^^^^^^^^^^^^^^
  File "C:\Users\RollPy\AppData\Local\pypoetry\Cache\virtualenvs\assistant-SImE5PKe-py3.12\Lib\site-packages\django\template\defaulttags.py", line 861, in do_for
    nodelist_loop = parser.parse(
                    ^^^^^^^^^^^^^
  File "C:\Users\RollPy\AppData\Local\pypoetry\Cache\virtualenvs\assistant-SImE5PKe-py3.12\Lib\site-packages\django\template\base.py", line 510, in parse
    raise self.error(token, e)
  File "C:\Users\RollPy\AppData\Local\pypoetry\Cache\virtualenvs\assistant-SImE5PKe-py3.12\Lib\site-packages\django\template\base.py", line 508, in parse
    compiled_result = compile_func(self, token)
                      ^^^^^^^^^^^^^^^^^^^^^^^^^
  File "C:\Users\RollPy\AppData\Local\pypoetry\Cache\virtualenvs\assistant-SImE5PKe-py3.12\Lib\site-packages\django\template\defaulttags.py", line 1397, in url
    args.append(parser.compile_filter(value))
                ^^^^^^^^^^^^^^^^^^^^^^^^^^^^
  File "C:\Users\RollPy\AppData\Local\pypoetry\Cache\virtualenvs\assistant-SImE5PKe-py3.12\Lib\site-packages\django\template\base.py", line 597, in compile_filter
    return FilterExpression(token, self)
           ^^^^^^^^^^^^^^^^^^^^^^^^^^^^^
  File "C:\Users\RollPy\AppData\Local\pypoetry\Cache\virtualenvs\assistant-SImE5PKe-py3.12\Lib\site-packages\django\template\base.py", line 698, in __init__
    raise TemplateSyntaxError(
django.template.exceptions.TemplateSyntaxError: Could not parse the remainder: '{{request.user.id}}' from '{{request.user.id}}'
Internal Server Error: /files/listfiles/
Traceback (most recent call last):
  File "C:\Users\RollPy\AppData\Local\pypoetry\Cache\virtualenvs\assistant-SImE5PKe-py3.12\Lib\site-packages\django\core\handlers\exception.py", line 55, in inner
    response = get_response(request)
               ^^^^^^^^^^^^^^^^^^^^^
  File "C:\Users\RollPy\AppData\Local\pypoetry\Cache\virtualenvs\assistant-SImE5PKe-py3.12\Lib\site-packages\django\core\handlers\base.py", line 197, in _get_response
    response = wrapped_callback(request, *callback_args, **callback_kwargs)
               ^^^^^^^^^^^^^^^^^^^^^^^^^^^^^^^^^^^^^^^^^^^^^^^^^^^^^^^^^^^^
  File "C:\Users\RollPy\Documents\GitHub\Django-Personal-Assistant\DPA\files\views.py", line 46, in get_filelist_from_drive
    return render(request, 'files/async_show_files_list.html',
           ^^^^^^^^^^^^^^^^^^^^^^^^^^^^^^^^^^^^^^^^^^^^^^^^^^^
  File "C:\Users\RollPy\AppData\Local\pypoetry\Cache\virtualenvs\assistant-SImE5PKe-py3.12\Lib\site-packages\django\shortcuts.py", line 25, in render
    content = loader.render_to_string(template_name, context, request, using=using)
              ^^^^^^^^^^^^^^^^^^^^^^^^^^^^^^^^^^^^^^^^^^^^^^^^^^^^^^^^^^^^^^^^^^^^^
  File "C:\Users\RollPy\AppData\Local\pypoetry\Cache\virtualenvs\assistant-SImE5PKe-py3.12\Lib\site-packages\django\template\loader.py", line 61, in render_to_string
    template = get_template(template_name, using=using)
               ^^^^^^^^^^^^^^^^^^^^^^^^^^^^^^^^^^^^^^^^
  File "C:\Users\RollPy\AppData\Local\pypoetry\Cache\virtualenvs\assistant-SImE5PKe-py3.12\Lib\site-packages\django\template\loader.py", line 15, in get_template
    return engine.get_template(template_name)
           ^^^^^^^^^^^^^^^^^^^^^^^^^^^^^^^^^^
  File "C:\Users\RollPy\AppData\Local\pypoetry\Cache\virtualenvs\assistant-SImE5PKe-py3.12\Lib\site-packages\django\template\backends\django.py", line 33, in get_template
    return Template(self.engine.get_template(template_name), self)
                    ^^^^^^^^^^^^^^^^^^^^^^^^^^^^^^^^^^^^^^^
  File "C:\Users\RollPy\AppData\Local\pypoetry\Cache\virtualenvs\assistant-SImE5PKe-py3.12\Lib\site-packages\django\template\engine.py", line 177, in get_template
    template, origin = self.find_template(template_name)
                       ^^^^^^^^^^^^^^^^^^^^^^^^^^^^^^^^^
  File "C:\Users\RollPy\AppData\Local\pypoetry\Cache\virtualenvs\assistant-SImE5PKe-py3.12\Lib\site-packages\django\template\engine.py", line 159, in find_template
    template = loader.get_template(name, skip=skip)
               ^^^^^^^^^^^^^^^^^^^^^^^^^^^^^^^^^^^^
  File "C:\Users\RollPy\AppData\Local\pypoetry\Cache\virtualenvs\assistant-SImE5PKe-py3.12\Lib\site-packages\django\template\loaders\cached.py", line 57, in get_template
    template = super().get_template(template_name, skip)
               ^^^^^^^^^^^^^^^^^^^^^^^^^^^^^^^^^^^^^^^^^
  File "C:\Users\RollPy\AppData\Local\pypoetry\Cache\virtualenvs\assistant-SImE5PKe-py3.12\Lib\site-packages\django\template\loaders\base.py", line 28, in get_template
    return Template(
           ^^^^^^^^^
  File "C:\Users\RollPy\AppData\Local\pypoetry\Cache\virtualenvs\assistant-SImE5PKe-py3.12\Lib\site-packages\django\template\base.py", line 154, in __init__
    self.nodelist = self.compile_nodelist()
                    ^^^^^^^^^^^^^^^^^^^^^^^
  File "C:\Users\RollPy\AppData\Local\pypoetry\Cache\virtualenvs\assistant-SImE5PKe-py3.12\Lib\site-packages\django\template\base.py", line 196, in compile_nodelist
    return parser.parse()
           ^^^^^^^^^^^^^^
  File "C:\Users\RollPy\AppData\Local\pypoetry\Cache\virtualenvs\assistant-SImE5PKe-py3.12\Lib\site-packages\django\template\base.py", line 510, in parse
    raise self.error(token, e)
  File "C:\Users\RollPy\AppData\Local\pypoetry\Cache\virtualenvs\assistant-SImE5PKe-py3.12\Lib\site-packages\django\template\base.py", line 508, in parse
    compiled_result = compile_func(self, token)
                      ^^^^^^^^^^^^^^^^^^^^^^^^^
  File "C:\Users\RollPy\AppData\Local\pypoetry\Cache\virtualenvs\assistant-SImE5PKe-py3.12\Lib\site-packages\django\template\defaulttags.py", line 861, in do_for
    nodelist_loop = parser.parse(
                    ^^^^^^^^^^^^^
  File "C:\Users\RollPy\AppData\Local\pypoetry\Cache\virtualenvs\assistant-SImE5PKe-py3.12\Lib\site-packages\django\template\base.py", line 510, in parse
    raise self.error(token, e)
  File "C:\Users\RollPy\AppData\Local\pypoetry\Cache\virtualenvs\assistant-SImE5PKe-py3.12\Lib\site-packages\django\template\base.py", line 508, in parse
    compiled_result = compile_func(self, token)
                      ^^^^^^^^^^^^^^^^^^^^^^^^^
  File "C:\Users\RollPy\AppData\Local\pypoetry\Cache\virtualenvs\assistant-SImE5PKe-py3.12\Lib\site-packages\django\template\defaulttags.py", line 1397, in url
    args.append(parser.compile_filter(value))
                ^^^^^^^^^^^^^^^^^^^^^^^^^^^^
  File "C:\Users\RollPy\AppData\Local\pypoetry\Cache\virtualenvs\assistant-SImE5PKe-py3.12\Lib\site-packages\django\template\base.py", line 597, in compile_filter
    return FilterExpression(token, self)
           ^^^^^^^^^^^^^^^^^^^^^^^^^^^^^
  File "C:\Users\RollPy\AppData\Local\pypoetry\Cache\virtualenvs\assistant-SImE5PKe-py3.12\Lib\site-packages\django\template\base.py", line 698, in __init__
    raise TemplateSyntaxError(
django.template.exceptions.TemplateSyntaxError: Could not parse the remainder: '{{request.user.id}}' from '{{request.user.id}}'
Internal Server Error: /files/delete/1L1IYdXXYxp1xiwoX-1LPCYtGp2x_Li1-/4
Traceback (most recent call last):
  File "C:\Users\RollPy\AppData\Local\pypoetry\Cache\virtualenvs\assistant-SImE5PKe-py3.12\Lib\site-packages\django\core\handlers\exception.py", line 55, in inner
    response = get_response(request)
               ^^^^^^^^^^^^^^^^^^^^^
  File "C:\Users\RollPy\AppData\Local\pypoetry\Cache\virtualenvs\assistant-SImE5PKe-py3.12\Lib\site-packages\django\core\handlers\base.py", line 197, in _get_response
    response = wrapped_callback(request, *callback_args, **callback_kwargs)
               ^^^^^^^^^^^^^^^^^^^^^^^^^^^^^^^^^^^^^^^^^^^^^^^^^^^^^^^^^^^^
  File "C:\Users\RollPy\AppData\Local\pypoetry\Cache\virtualenvs\assistant-SImE5PKe-py3.12\Lib\site-packages\asgiref\sync.py", line 254, in __call__
    return call_result.result()
           ^^^^^^^^^^^^^^^^^^^^
  File "C:\Users\RollPy\AppData\Local\Programs\Python\Python312\Lib\concurrent\futures\_base.py", line 449, in result
    return self.__get_result()
           ^^^^^^^^^^^^^^^^^^^
  File "C:\Users\RollPy\AppData\Local\Programs\Python\Python312\Lib\concurrent\futures\_base.py", line 401, in __get_result
    raise self._exception
  File "C:\Users\RollPy\AppData\Local\pypoetry\Cache\virtualenvs\assistant-SImE5PKe-py3.12\Lib\site-packages\asgiref\sync.py", line 331, in main_wrap
    result = await self.awaitable(*args, **kwargs)
             ^^^^^^^^^^^^^^^^^^^^^^^^^^^^^^^^^^^^^
  File "C:\Users\RollPy\Documents\GitHub\Django-Personal-Assistant\DPA\files\views.py", line 186, in delete_file
    await aiogoogle.as_user(
  File "C:\Users\RollPy\AppData\Local\pypoetry\Cache\virtualenvs\assistant-SImE5PKe-py3.12\Lib\site-packages\aiogoogle\client.py", line 254, in as_user
    return await self.send(
           ^^^^^^^^^^^^^^^^
  File "C:\Users\RollPy\AppData\Local\pypoetry\Cache\virtualenvs\assistant-SImE5PKe-py3.12\Lib\site-packages\aiogoogle\client.py", line 409, in send
    return await session.send(*args, **kwargs)
           ^^^^^^^^^^^^^^^^^^^^^^^^^^^^^^^^^^^
  File "C:\Users\RollPy\AppData\Local\pypoetry\Cache\virtualenvs\assistant-SImE5PKe-py3.12\Lib\site-packages\aiogoogle\sessions\aiohttp_session.py", line 186, in send
    results = await schedule_tasks()
              ^^^^^^^^^^^^^^^^^^^^^^
  File "C:\Users\RollPy\AppData\Local\pypoetry\Cache\virtualenvs\assistant-SImE5PKe-py3.12\Lib\site-packages\aiogoogle\sessions\aiohttp_session.py", line 171, in schedule_tasks
    return await asyncio.gather(
           ^^^^^^^^^^^^^^^^^^^^^
  File "C:\Users\RollPy\AppData\Local\pypoetry\Cache\virtualenvs\assistant-SImE5PKe-py3.12\Lib\site-packages\aiogoogle\sessions\aiohttp_session.py", line 165, in get_content
    response = await get_response(request)
               ^^^^^^^^^^^^^^^^^^^^^^^^^^^
  File "C:\Users\RollPy\AppData\Local\pypoetry\Cache\virtualenvs\assistant-SImE5PKe-py3.12\Lib\site-packages\aiogoogle\sessions\aiohttp_session.py", line 161, in get_response
    response.raise_for_status()
  File "C:\Users\RollPy\AppData\Local\pypoetry\Cache\virtualenvs\assistant-SImE5PKe-py3.12\Lib\site-packages\aiogoogle\models.py", line 480, in raise_for_status
    raise HTTPError(msg=self.reason, req=self.req, res=self)
aiogoogle.excs.HTTPError: 



Not Found

Content:
{'code': 404,
 'errors': [{'domain': 'global',
             'location': 'fileId',
             'locationType': 'parameter',
             'message': 'File not found: 1L1IYdXXYxp1xiwoX-1LPCYtGp2x_Li1-.',
             'reason': 'notFound'}],
 'message': 'File not found: 1L1IYdXXYxp1xiwoX-1LPCYtGp2x_Li1-.'}

Request URL:
https://www.googleapis.com/drive/v3/files/1L1IYdXXYxp1xiwoX-1LPCYtGp2x_Li1-
Internal Server Error: /files/delete/1JED2vhfDvxMa3bb1rFZ3SOinjnr9FOdc/4
Traceback (most recent call last):
  File "C:\Users\RollPy\AppData\Local\pypoetry\Cache\virtualenvs\assistant-SImE5PKe-py3.12\Lib\site-packages\django\core\handlers\exception.py", line 55, in inner
    response = get_response(request)
               ^^^^^^^^^^^^^^^^^^^^^
  File "C:\Users\RollPy\AppData\Local\pypoetry\Cache\virtualenvs\assistant-SImE5PKe-py3.12\Lib\site-packages\django\core\handlers\base.py", line 197, in _get_response
    response = wrapped_callback(request, *callback_args, **callback_kwargs)
               ^^^^^^^^^^^^^^^^^^^^^^^^^^^^^^^^^^^^^^^^^^^^^^^^^^^^^^^^^^^^
  File "C:\Users\RollPy\AppData\Local\pypoetry\Cache\virtualenvs\assistant-SImE5PKe-py3.12\Lib\site-packages\asgiref\sync.py", line 254, in __call__
    return call_result.result()
           ^^^^^^^^^^^^^^^^^^^^
  File "C:\Users\RollPy\AppData\Local\Programs\Python\Python312\Lib\concurrent\futures\_base.py", line 449, in result
    return self.__get_result()
           ^^^^^^^^^^^^^^^^^^^
  File "C:\Users\RollPy\AppData\Local\Programs\Python\Python312\Lib\concurrent\futures\_base.py", line 401, in __get_result
    raise self._exception
  File "C:\Users\RollPy\AppData\Local\pypoetry\Cache\virtualenvs\assistant-SImE5PKe-py3.12\Lib\site-packages\asgiref\sync.py", line 331, in main_wrap
    result = await self.awaitable(*args, **kwargs)
             ^^^^^^^^^^^^^^^^^^^^^^^^^^^^^^^^^^^^^
  File "C:\Users\RollPy\Documents\GitHub\Django-Personal-Assistant\DPA\files\views.py", line 189, in delete_file
    get_cache_data(request="Mock", user_id=user_id)
  File "C:\Users\RollPy\Documents\GitHub\Django-Personal-Assistant\DPA\files\views.py", line 21, in get_cache_data
    data = async_to_sync(get_file_list_from_drive)(get_folder_id_by_user(user_id))
                                                   ^^^^^^^^^^^^^^^^^^^^^^^^^^^^^^
  File "C:\Users\RollPy\Documents\GitHub\Django-Personal-Assistant\DPA\files\views.py", line 30, in get_folder_id_by_user
    with transaction.atomic():
  File "C:\Users\RollPy\AppData\Local\pypoetry\Cache\virtualenvs\assistant-SImE5PKe-py3.12\Lib\site-packages\django\db\transaction.py", line 198, in __enter__
    if not connection.get_autocommit():
           ^^^^^^^^^^^^^^^^^^^^^^^^^^^
  File "C:\Users\RollPy\AppData\Local\pypoetry\Cache\virtualenvs\assistant-SImE5PKe-py3.12\Lib\site-packages\django\db\backends\base\base.py", line 450, in get_autocommit
    self.ensure_connection()
  File "C:\Users\RollPy\AppData\Local\pypoetry\Cache\virtualenvs\assistant-SImE5PKe-py3.12\Lib\site-packages\django\utils\asyncio.py", line 24, in inner
    raise SynchronousOnlyOperation(message)
django.core.exceptions.SynchronousOnlyOperation: You cannot call this from an async context - use a thread or sync_to_async.
Internal Server Error: /files/delete/1PnpNjU7mAwxvZzvpcjOnacLXJIXUxhqM/4
Traceback (most recent call last):
  File "C:\Users\RollPy\AppData\Local\pypoetry\Cache\virtualenvs\assistant-SImE5PKe-py3.12\Lib\site-packages\django\core\handlers\exception.py", line 55, in inner
    response = get_response(request)
               ^^^^^^^^^^^^^^^^^^^^^
  File "C:\Users\RollPy\AppData\Local\pypoetry\Cache\virtualenvs\assistant-SImE5PKe-py3.12\Lib\site-packages\django\core\handlers\base.py", line 197, in _get_response
    response = wrapped_callback(request, *callback_args, **callback_kwargs)
               ^^^^^^^^^^^^^^^^^^^^^^^^^^^^^^^^^^^^^^^^^^^^^^^^^^^^^^^^^^^^
  File "C:\Users\RollPy\AppData\Local\pypoetry\Cache\virtualenvs\assistant-SImE5PKe-py3.12\Lib\site-packages\asgiref\sync.py", line 254, in __call__
    return call_result.result()
           ^^^^^^^^^^^^^^^^^^^^
  File "C:\Users\RollPy\AppData\Local\Programs\Python\Python312\Lib\concurrent\futures\_base.py", line 449, in result
    return self.__get_result()
           ^^^^^^^^^^^^^^^^^^^
  File "C:\Users\RollPy\AppData\Local\Programs\Python\Python312\Lib\concurrent\futures\_base.py", line 401, in __get_result
    raise self._exception
  File "C:\Users\RollPy\AppData\Local\pypoetry\Cache\virtualenvs\assistant-SImE5PKe-py3.12\Lib\site-packages\asgiref\sync.py", line 331, in main_wrap
    result = await self.awaitable(*args, **kwargs)
             ^^^^^^^^^^^^^^^^^^^^^^^^^^^^^^^^^^^^^
  File "C:\Users\RollPy\Documents\GitHub\Django-Personal-Assistant\DPA\files\views.py", line 189, in delete_file
    get_cache_data('mock', user_id=user_id)
  File "C:\Users\RollPy\Documents\GitHub\Django-Personal-Assistant\DPA\files\views.py", line 21, in get_cache_data
    data = async_to_sync(get_file_list_from_drive)(get_folder_id_by_user(user_id))
                                                   ^^^^^^^^^^^^^^^^^^^^^^^^^^^^^^
  File "C:\Users\RollPy\Documents\GitHub\Django-Personal-Assistant\DPA\files\views.py", line 30, in get_folder_id_by_user
    with transaction.atomic():
  File "C:\Users\RollPy\AppData\Local\pypoetry\Cache\virtualenvs\assistant-SImE5PKe-py3.12\Lib\site-packages\django\db\transaction.py", line 198, in __enter__
    if not connection.get_autocommit():
           ^^^^^^^^^^^^^^^^^^^^^^^^^^^
  File "C:\Users\RollPy\AppData\Local\pypoetry\Cache\virtualenvs\assistant-SImE5PKe-py3.12\Lib\site-packages\django\db\backends\base\base.py", line 450, in get_autocommit
    self.ensure_connection()
  File "C:\Users\RollPy\AppData\Local\pypoetry\Cache\virtualenvs\assistant-SImE5PKe-py3.12\Lib\site-packages\django\utils\asyncio.py", line 24, in inner
    raise SynchronousOnlyOperation(message)
django.core.exceptions.SynchronousOnlyOperation: You cannot call this from an async context - use a thread or sync_to_async.
Internal Server Error: /files/delete/1sP6GN5xJv2qejKeOLWnmlSH047vGuVan/4
Traceback (most recent call last):
  File "C:\Users\RollPy\AppData\Local\pypoetry\Cache\virtualenvs\assistant-SImE5PKe-py3.12\Lib\site-packages\django\core\handlers\exception.py", line 55, in inner
    response = get_response(request)
               ^^^^^^^^^^^^^^^^^^^^^
  File "C:\Users\RollPy\AppData\Local\pypoetry\Cache\virtualenvs\assistant-SImE5PKe-py3.12\Lib\site-packages\django\core\handlers\base.py", line 197, in _get_response
    response = wrapped_callback(request, *callback_args, **callback_kwargs)
               ^^^^^^^^^^^^^^^^^^^^^^^^^^^^^^^^^^^^^^^^^^^^^^^^^^^^^^^^^^^^
  File "C:\Users\RollPy\AppData\Local\pypoetry\Cache\virtualenvs\assistant-SImE5PKe-py3.12\Lib\site-packages\asgiref\sync.py", line 254, in __call__
    return call_result.result()
           ^^^^^^^^^^^^^^^^^^^^
  File "C:\Users\RollPy\AppData\Local\Programs\Python\Python312\Lib\concurrent\futures\_base.py", line 449, in result
    return self.__get_result()
           ^^^^^^^^^^^^^^^^^^^
  File "C:\Users\RollPy\AppData\Local\Programs\Python\Python312\Lib\concurrent\futures\_base.py", line 401, in __get_result
    raise self._exception
  File "C:\Users\RollPy\AppData\Local\pypoetry\Cache\virtualenvs\assistant-SImE5PKe-py3.12\Lib\site-packages\asgiref\sync.py", line 331, in main_wrap
    result = await self.awaitable(*args, **kwargs)
             ^^^^^^^^^^^^^^^^^^^^^^^^^^^^^^^^^^^^^
  File "C:\Users\RollPy\Documents\GitHub\Django-Personal-Assistant\DPA\files\views.py", line 190, in delete_file
    await sync_to_async(get_cache_data)('mock', user_id=user_id)
  File "C:\Users\RollPy\AppData\Local\pypoetry\Cache\virtualenvs\assistant-SImE5PKe-py3.12\Lib\site-packages\asgiref\sync.py", line 468, in __call__
    ret = await asyncio.shield(exec_coro)
          ^^^^^^^^^^^^^^^^^^^^^^^^^^^^^^^
  File "C:\Users\RollPy\AppData\Local\pypoetry\Cache\virtualenvs\assistant-SImE5PKe-py3.12\Lib\site-packages\asgiref\current_thread_executor.py", line 40, in run
    result = self.fn(*self.args, **self.kwargs)
             ^^^^^^^^^^^^^^^^^^^^^^^^^^^^^^^^^^
  File "C:\Users\RollPy\AppData\Local\pypoetry\Cache\virtualenvs\assistant-SImE5PKe-py3.12\Lib\site-packages\asgiref\sync.py", line 522, in thread_handler
    return func(*args, **kwargs)
           ^^^^^^^^^^^^^^^^^^^^^
  File "C:\Users\RollPy\Documents\GitHub\Django-Personal-Assistant\DPA\files\views.py", line 25, in get_cache_data
    data = async_to_sync(get_file_list_from_drive)(get_folder_id_by_user(request.user))
                                                                         ^^^^^^^^^^^^
AttributeError: 'str' object has no attribute 'user'
Internal Server Error: /files/delete/1Oowo6jHyB3Ojsvs7p3tC3SHK8eM3pVzI/
Traceback (most recent call last):
  File "C:\Users\RollPy\AppData\Local\pypoetry\Cache\virtualenvs\assistant-SImE5PKe-py3.12\Lib\site-packages\django\core\handlers\exception.py", line 55, in inner
    response = get_response(request)
               ^^^^^^^^^^^^^^^^^^^^^
  File "C:\Users\RollPy\AppData\Local\pypoetry\Cache\virtualenvs\assistant-SImE5PKe-py3.12\Lib\site-packages\django\core\handlers\base.py", line 197, in _get_response
    response = wrapped_callback(request, *callback_args, **callback_kwargs)
               ^^^^^^^^^^^^^^^^^^^^^^^^^^^^^^^^^^^^^^^^^^^^^^^^^^^^^^^^^^^^
  File "C:\Users\RollPy\AppData\Local\pypoetry\Cache\virtualenvs\assistant-SImE5PKe-py3.12\Lib\site-packages\asgiref\sync.py", line 254, in __call__
    return call_result.result()
           ^^^^^^^^^^^^^^^^^^^^
  File "C:\Users\RollPy\AppData\Local\Programs\Python\Python312\Lib\concurrent\futures\_base.py", line 449, in result
    return self.__get_result()
           ^^^^^^^^^^^^^^^^^^^
  File "C:\Users\RollPy\AppData\Local\Programs\Python\Python312\Lib\concurrent\futures\_base.py", line 401, in __get_result
    raise self._exception
  File "C:\Users\RollPy\AppData\Local\pypoetry\Cache\virtualenvs\assistant-SImE5PKe-py3.12\Lib\site-packages\asgiref\sync.py", line 331, in main_wrap
    result = await self.awaitable(*args, **kwargs)
                   ^^^^^^^^^^^^^^^^^^^^^^^^^^^^^^^
TypeError: delete_file() missing 1 required positional argument: 'user_id'
Internal Server Error: /files/images/
Traceback (most recent call last):
  File "C:\Users\RollPy\AppData\Local\pypoetry\Cache\virtualenvs\assistant-SImE5PKe-py3.12\Lib\site-packages\django\core\handlers\exception.py", line 55, in inner
    response = get_response(request)
               ^^^^^^^^^^^^^^^^^^^^^
  File "C:\Users\RollPy\AppData\Local\pypoetry\Cache\virtualenvs\assistant-SImE5PKe-py3.12\Lib\site-packages\django\core\handlers\base.py", line 197, in _get_response
    response = wrapped_callback(request, *callback_args, **callback_kwargs)
               ^^^^^^^^^^^^^^^^^^^^^^^^^^^^^^^^^^^^^^^^^^^^^^^^^^^^^^^^^^^^
  File "C:\Users\RollPy\Documents\GitHub\Django-Personal-Assistant\DPA\files\views.py", line 195, in show_images
    return render(request, 'files/images.html', context={'images': data['images']})
           ^^^^^^^^^^^^^^^^^^^^^^^^^^^^^^^^^^^^^^^^^^^^^^^^^^^^^^^^^^^^^^^^^^^^^^^^
  File "C:\Users\RollPy\AppData\Local\pypoetry\Cache\virtualenvs\assistant-SImE5PKe-py3.12\Lib\site-packages\django\shortcuts.py", line 25, in render
    content = loader.render_to_string(template_name, context, request, using=using)
              ^^^^^^^^^^^^^^^^^^^^^^^^^^^^^^^^^^^^^^^^^^^^^^^^^^^^^^^^^^^^^^^^^^^^^
  File "C:\Users\RollPy\AppData\Local\pypoetry\Cache\virtualenvs\assistant-SImE5PKe-py3.12\Lib\site-packages\django\template\loader.py", line 62, in render_to_string
    return template.render(context, request)
           ^^^^^^^^^^^^^^^^^^^^^^^^^^^^^^^^^
  File "C:\Users\RollPy\AppData\Local\pypoetry\Cache\virtualenvs\assistant-SImE5PKe-py3.12\Lib\site-packages\django\template\backends\django.py", line 61, in render
    return self.template.render(context)
           ^^^^^^^^^^^^^^^^^^^^^^^^^^^^^
  File "C:\Users\RollPy\AppData\Local\pypoetry\Cache\virtualenvs\assistant-SImE5PKe-py3.12\Lib\site-packages\django\template\base.py", line 171, in render
    return self._render(context)
           ^^^^^^^^^^^^^^^^^^^^^
  File "C:\Users\RollPy\AppData\Local\pypoetry\Cache\virtualenvs\assistant-SImE5PKe-py3.12\Lib\site-packages\django\template\base.py", line 163, in _render
    return self.nodelist.render(context)
           ^^^^^^^^^^^^^^^^^^^^^^^^^^^^^
  File "C:\Users\RollPy\AppData\Local\pypoetry\Cache\virtualenvs\assistant-SImE5PKe-py3.12\Lib\site-packages\django\template\base.py", line 1000, in render
    return SafeString("".join([node.render_annotated(context) for node in self]))
                               ^^^^^^^^^^^^^^^^^^^^^^^^^^^^^^
  File "C:\Users\RollPy\AppData\Local\pypoetry\Cache\virtualenvs\assistant-SImE5PKe-py3.12\Lib\site-packages\django\template\base.py", line 961, in render_annotated
    return self.render(context)
           ^^^^^^^^^^^^^^^^^^^^
  File "C:\Users\RollPy\AppData\Local\pypoetry\Cache\virtualenvs\assistant-SImE5PKe-py3.12\Lib\site-packages\django\template\defaulttags.py", line 242, in render
    nodelist.append(node.render_annotated(context))
                    ^^^^^^^^^^^^^^^^^^^^^^^^^^^^^^
  File "C:\Users\RollPy\AppData\Local\pypoetry\Cache\virtualenvs\assistant-SImE5PKe-py3.12\Lib\site-packages\django\template\base.py", line 961, in render_annotated
    return self.render(context)
           ^^^^^^^^^^^^^^^^^^^^
  File "C:\Users\RollPy\AppData\Local\pypoetry\Cache\virtualenvs\assistant-SImE5PKe-py3.12\Lib\site-packages\django\template\defaulttags.py", line 479, in render
    url = reverse(view_name, args=args, kwargs=kwargs, current_app=current_app)
          ^^^^^^^^^^^^^^^^^^^^^^^^^^^^^^^^^^^^^^^^^^^^^^^^^^^^^^^^^^^^^^^^^^^^^
  File "C:\Users\RollPy\AppData\Local\pypoetry\Cache\virtualenvs\assistant-SImE5PKe-py3.12\Lib\site-packages\django\urls\base.py", line 88, in reverse
    return resolver._reverse_with_prefix(view, prefix, *args, **kwargs)
           ^^^^^^^^^^^^^^^^^^^^^^^^^^^^^^^^^^^^^^^^^^^^^^^^^^^^^^^^^^^^
  File "C:\Users\RollPy\AppData\Local\pypoetry\Cache\virtualenvs\assistant-SImE5PKe-py3.12\Lib\site-packages\django\urls\resolvers.py", line 851, in _reverse_with_prefix
    raise NoReverseMatch(msg)
django.urls.exceptions.NoReverseMatch: Reverse for 'download_file' with arguments '('1I5tAmA5YgdplbCXqb7ze4VXhZF8C5oGp', 'images')' not found. 1 pattern(s) tried: ['files/download/(?P<file_id>[^/]+)/\\Z']
Internal Server Error: /files/images/
Traceback (most recent call last):
  File "C:\Users\RollPy\AppData\Local\pypoetry\Cache\virtualenvs\assistant-SImE5PKe-py3.12\Lib\site-packages\django\template\base.py", line 502, in parse
    compile_func = self.tags[command]
                   ~~~~~~~~~^^^^^^^^^
KeyError: 'endfor'

During handling of the above exception, another exception occurred:

Traceback (most recent call last):
  File "C:\Users\RollPy\AppData\Local\pypoetry\Cache\virtualenvs\assistant-SImE5PKe-py3.12\Lib\site-packages\django\core\handlers\exception.py", line 55, in inner
    response = get_response(request)
               ^^^^^^^^^^^^^^^^^^^^^
  File "C:\Users\RollPy\AppData\Local\pypoetry\Cache\virtualenvs\assistant-SImE5PKe-py3.12\Lib\site-packages\django\core\handlers\base.py", line 197, in _get_response
    response = wrapped_callback(request, *callback_args, **callback_kwargs)
               ^^^^^^^^^^^^^^^^^^^^^^^^^^^^^^^^^^^^^^^^^^^^^^^^^^^^^^^^^^^^
  File "C:\Users\RollPy\Documents\GitHub\Django-Personal-Assistant\DPA\files\views.py", line 201, in show_images
    return render(request, 'files/images.html', context={'images': data['images']})
           ^^^^^^^^^^^^^^^^^^^^^^^^^^^^^^^^^^^^^^^^^^^^^^^^^^^^^^^^^^^^^^^^^^^^^^^^
  File "C:\Users\RollPy\AppData\Local\pypoetry\Cache\virtualenvs\assistant-SImE5PKe-py3.12\Lib\site-packages\django\shortcuts.py", line 25, in render
    content = loader.render_to_string(template_name, context, request, using=using)
              ^^^^^^^^^^^^^^^^^^^^^^^^^^^^^^^^^^^^^^^^^^^^^^^^^^^^^^^^^^^^^^^^^^^^^
  File "C:\Users\RollPy\AppData\Local\pypoetry\Cache\virtualenvs\assistant-SImE5PKe-py3.12\Lib\site-packages\django\template\loader.py", line 61, in render_to_string
    template = get_template(template_name, using=using)
               ^^^^^^^^^^^^^^^^^^^^^^^^^^^^^^^^^^^^^^^^
  File "C:\Users\RollPy\AppData\Local\pypoetry\Cache\virtualenvs\assistant-SImE5PKe-py3.12\Lib\site-packages\django\template\loader.py", line 15, in get_template
    return engine.get_template(template_name)
           ^^^^^^^^^^^^^^^^^^^^^^^^^^^^^^^^^^
  File "C:\Users\RollPy\AppData\Local\pypoetry\Cache\virtualenvs\assistant-SImE5PKe-py3.12\Lib\site-packages\django\template\backends\django.py", line 33, in get_template
    return Template(self.engine.get_template(template_name), self)
                    ^^^^^^^^^^^^^^^^^^^^^^^^^^^^^^^^^^^^^^^
  File "C:\Users\RollPy\AppData\Local\pypoetry\Cache\virtualenvs\assistant-SImE5PKe-py3.12\Lib\site-packages\django\template\engine.py", line 177, in get_template
    template, origin = self.find_template(template_name)
                       ^^^^^^^^^^^^^^^^^^^^^^^^^^^^^^^^^
  File "C:\Users\RollPy\AppData\Local\pypoetry\Cache\virtualenvs\assistant-SImE5PKe-py3.12\Lib\site-packages\django\template\engine.py", line 159, in find_template
    template = loader.get_template(name, skip=skip)
               ^^^^^^^^^^^^^^^^^^^^^^^^^^^^^^^^^^^^
  File "C:\Users\RollPy\AppData\Local\pypoetry\Cache\virtualenvs\assistant-SImE5PKe-py3.12\Lib\site-packages\django\template\loaders\cached.py", line 57, in get_template
    template = super().get_template(template_name, skip)
               ^^^^^^^^^^^^^^^^^^^^^^^^^^^^^^^^^^^^^^^^^
  File "C:\Users\RollPy\AppData\Local\pypoetry\Cache\virtualenvs\assistant-SImE5PKe-py3.12\Lib\site-packages\django\template\loaders\base.py", line 28, in get_template
    return Template(
           ^^^^^^^^^
  File "C:\Users\RollPy\AppData\Local\pypoetry\Cache\virtualenvs\assistant-SImE5PKe-py3.12\Lib\site-packages\django\template\base.py", line 154, in __init__
    self.nodelist = self.compile_nodelist()
                    ^^^^^^^^^^^^^^^^^^^^^^^
  File "C:\Users\RollPy\AppData\Local\pypoetry\Cache\virtualenvs\assistant-SImE5PKe-py3.12\Lib\site-packages\django\template\base.py", line 196, in compile_nodelist
    return parser.parse()
           ^^^^^^^^^^^^^^
  File "C:\Users\RollPy\AppData\Local\pypoetry\Cache\virtualenvs\assistant-SImE5PKe-py3.12\Lib\site-packages\django\template\base.py", line 504, in parse
    self.invalid_block_tag(token, command, parse_until)
  File "C:\Users\RollPy\AppData\Local\pypoetry\Cache\virtualenvs\assistant-SImE5PKe-py3.12\Lib\site-packages\django\template\base.py", line 565, in invalid_block_tag
    raise self.error(
django.template.exceptions.TemplateSyntaxError: Invalid block tag on line 72: 'endfor'. Did you forget to register or load this tag?
Not Found: /files/open/1XCNzyLm0CewSW2AykaTpYfALquzeTB6Z/ target='_blank'
Not Found: /files/open/1XCNzyLm0CewSW2AykaTpYfALquzeTB6Z/ target=
Not Found: /files//files/videos/
Not Found: /files//files/videos/
Not Found: /files//files/videos/
Not Found: /files//files/videos/
Internal Server Error: /files/upload/
Traceback (most recent call last):
  File "C:\Users\RollPy\AppData\Local\pypoetry\Cache\virtualenvs\assistant-SImE5PKe-py3.12\Lib\site-packages\django\db\backends\base\base.py", line 275, in ensure_connection
    self.connect()
  File "C:\Users\RollPy\AppData\Local\pypoetry\Cache\virtualenvs\assistant-SImE5PKe-py3.12\Lib\site-packages\django\utils\asyncio.py", line 26, in inner
    return func(*args, **kwargs)
           ^^^^^^^^^^^^^^^^^^^^^
  File "C:\Users\RollPy\AppData\Local\pypoetry\Cache\virtualenvs\assistant-SImE5PKe-py3.12\Lib\site-packages\django\db\backends\base\base.py", line 256, in connect
    self.connection = self.get_new_connection(conn_params)
                      ^^^^^^^^^^^^^^^^^^^^^^^^^^^^^^^^^^^^
  File "C:\Users\RollPy\AppData\Local\pypoetry\Cache\virtualenvs\assistant-SImE5PKe-py3.12\Lib\site-packages\django\utils\asyncio.py", line 26, in inner
    return func(*args, **kwargs)
           ^^^^^^^^^^^^^^^^^^^^^
  File "C:\Users\RollPy\AppData\Local\pypoetry\Cache\virtualenvs\assistant-SImE5PKe-py3.12\Lib\site-packages\django\db\backends\postgresql\base.py", line 277, in get_new_connection
    connection = self.Database.connect(**conn_params)
                 ^^^^^^^^^^^^^^^^^^^^^^^^^^^^^^^^^^^^
  File "C:\Users\RollPy\AppData\Local\pypoetry\Cache\virtualenvs\assistant-SImE5PKe-py3.12\Lib\site-packages\psycopg2\__init__.py", line 122, in connect
    conn = _connect(dsn, connection_factory=connection_factory, **kwasync)
           ^^^^^^^^^^^^^^^^^^^^^^^^^^^^^^^^^^^^^^^^^^^^^^^^^^^^^^^^^^^^^^^
psycopg2.OperationalError: connection to server at "dpg-cop8gr0cmk4c739q4v60-a.frankfurt-postgres.render.com" (3.120.236.187), port 5432 failed: SSL connection has been closed unexpectedly


The above exception was the direct cause of the following exception:

Traceback (most recent call last):
  File "C:\Users\RollPy\AppData\Local\pypoetry\Cache\virtualenvs\assistant-SImE5PKe-py3.12\Lib\site-packages\django\core\handlers\exception.py", line 55, in inner
    response = get_response(request)
               ^^^^^^^^^^^^^^^^^^^^^
  File "C:\Users\RollPy\AppData\Local\pypoetry\Cache\virtualenvs\assistant-SImE5PKe-py3.12\Lib\site-packages\django\core\handlers\base.py", line 197, in _get_response
    response = wrapped_callback(request, *callback_args, **callback_kwargs)
               ^^^^^^^^^^^^^^^^^^^^^^^^^^^^^^^^^^^^^^^^^^^^^^^^^^^^^^^^^^^^
  File "C:\Users\RollPy\Documents\GitHub\Django-Personal-Assistant\DPA\files\views.py", line 123, in upload_file
    folder_id = get_folder_id_by_user(request.user)
                ^^^^^^^^^^^^^^^^^^^^^^^^^^^^^^^^^^^
  File "C:\Users\RollPy\Documents\GitHub\Django-Personal-Assistant\DPA\files\views.py", line 26, in get_folder_id_by_user
    with transaction.atomic():
  File "C:\Users\RollPy\AppData\Local\pypoetry\Cache\virtualenvs\assistant-SImE5PKe-py3.12\Lib\site-packages\django\db\transaction.py", line 198, in __enter__
    if not connection.get_autocommit():
           ^^^^^^^^^^^^^^^^^^^^^^^^^^^
  File "C:\Users\RollPy\AppData\Local\pypoetry\Cache\virtualenvs\assistant-SImE5PKe-py3.12\Lib\site-packages\django\db\backends\base\base.py", line 450, in get_autocommit
    self.ensure_connection()
  File "C:\Users\RollPy\AppData\Local\pypoetry\Cache\virtualenvs\assistant-SImE5PKe-py3.12\Lib\site-packages\django\utils\asyncio.py", line 26, in inner
    return func(*args, **kwargs)
           ^^^^^^^^^^^^^^^^^^^^^
  File "C:\Users\RollPy\AppData\Local\pypoetry\Cache\virtualenvs\assistant-SImE5PKe-py3.12\Lib\site-packages\django\db\backends\base\base.py", line 274, in ensure_connection
    with self.wrap_database_errors:
  File "C:\Users\RollPy\AppData\Local\pypoetry\Cache\virtualenvs\assistant-SImE5PKe-py3.12\Lib\site-packages\django\db\utils.py", line 91, in __exit__
    raise dj_exc_value.with_traceback(traceback) from exc_value
  File "C:\Users\RollPy\AppData\Local\pypoetry\Cache\virtualenvs\assistant-SImE5PKe-py3.12\Lib\site-packages\django\db\backends\base\base.py", line 275, in ensure_connection
    self.connect()
  File "C:\Users\RollPy\AppData\Local\pypoetry\Cache\virtualenvs\assistant-SImE5PKe-py3.12\Lib\site-packages\django\utils\asyncio.py", line 26, in inner
    return func(*args, **kwargs)
           ^^^^^^^^^^^^^^^^^^^^^
  File "C:\Users\RollPy\AppData\Local\pypoetry\Cache\virtualenvs\assistant-SImE5PKe-py3.12\Lib\site-packages\django\db\backends\base\base.py", line 256, in connect
    self.connection = self.get_new_connection(conn_params)
                      ^^^^^^^^^^^^^^^^^^^^^^^^^^^^^^^^^^^^
  File "C:\Users\RollPy\AppData\Local\pypoetry\Cache\virtualenvs\assistant-SImE5PKe-py3.12\Lib\site-packages\django\utils\asyncio.py", line 26, in inner
    return func(*args, **kwargs)
           ^^^^^^^^^^^^^^^^^^^^^
  File "C:\Users\RollPy\AppData\Local\pypoetry\Cache\virtualenvs\assistant-SImE5PKe-py3.12\Lib\site-packages\django\db\backends\postgresql\base.py", line 277, in get_new_connection
    connection = self.Database.connect(**conn_params)
                 ^^^^^^^^^^^^^^^^^^^^^^^^^^^^^^^^^^^^
  File "C:\Users\RollPy\AppData\Local\pypoetry\Cache\virtualenvs\assistant-SImE5PKe-py3.12\Lib\site-packages\psycopg2\__init__.py", line 122, in connect
    conn = _connect(dsn, connection_factory=connection_factory, **kwasync)
           ^^^^^^^^^^^^^^^^^^^^^^^^^^^^^^^^^^^^^^^^^^^^^^^^^^^^^^^^^^^^^^^
django.db.utils.OperationalError: connection to server at "dpg-cop8gr0cmk4c739q4v60-a.frankfurt-postgres.render.com" (3.120.236.187), port 5432 failed: SSL connection has been closed unexpectedly

Not Found: /favicon.ico
Not Found: /favicon.ico
Not Found: /favicon.ico
Internal Server Error: /
Traceback (most recent call last):
  File "C:\Users\bened\AppData\Local\pypoetry\Cache\virtualenvs\assistant-Mp1SmFtH-py3.12\Lib\site-packages\django\core\handlers\exception.py", line 55, in inner
    response = get_response(request)
               ^^^^^^^^^^^^^^^^^^^^^
  File "C:\Users\bened\AppData\Local\pypoetry\Cache\virtualenvs\assistant-Mp1SmFtH-py3.12\Lib\site-packages\django\core\handlers\base.py", line 197, in _get_response
    response = wrapped_callback(request, *callback_args, **callback_kwargs)
               ^^^^^^^^^^^^^^^^^^^^^^^^^^^^^^^^^^^^^^^^^^^^^^^^^^^^^^^^^^^^
  File "C:\Users\bened\Documents\coding\DPA1\Django-Personal-Assistant\DPA\users\views.py", line 131, in index
    finance_news = get_finance_news()
                   ^^^^^^^^^^^^^^^^
NameError: name 'get_finance_news' is not defined. Did you mean: 'scrape_finance_news'?
Internal Server Error: /
Traceback (most recent call last):
  File "C:\Users\bened\AppData\Local\pypoetry\Cache\virtualenvs\assistant-Mp1SmFtH-py3.12\Lib\site-packages\django\core\handlers\exception.py", line 55, in inner
    response = get_response(request)
               ^^^^^^^^^^^^^^^^^^^^^
  File "C:\Users\bened\AppData\Local\pypoetry\Cache\virtualenvs\assistant-Mp1SmFtH-py3.12\Lib\site-packages\django\core\handlers\base.py", line 197, in _get_response
    response = wrapped_callback(request, *callback_args, **callback_kwargs)
               ^^^^^^^^^^^^^^^^^^^^^^^^^^^^^^^^^^^^^^^^^^^^^^^^^^^^^^^^^^^^
  File "C:\Users\bened\Documents\coding\DPA1\Django-Personal-Assistant\DPA\users\views.py", line 131, in index
    finance_news = get_finance_news()
                   ^^^^^^^^^^^^^^^^
NameError: name 'get_finance_news' is not defined. Did you mean: 'scrape_finance_news'?
Internal Server Error: /
Traceback (most recent call last):
  File "C:\Users\bened\AppData\Local\pypoetry\Cache\virtualenvs\assistant-Mp1SmFtH-py3.12\Lib\site-packages\django\core\handlers\exception.py", line 55, in inner
    response = get_response(request)
               ^^^^^^^^^^^^^^^^^^^^^
  File "C:\Users\bened\AppData\Local\pypoetry\Cache\virtualenvs\assistant-Mp1SmFtH-py3.12\Lib\site-packages\django\core\handlers\base.py", line 197, in _get_response
    response = wrapped_callback(request, *callback_args, **callback_kwargs)
               ^^^^^^^^^^^^^^^^^^^^^^^^^^^^^^^^^^^^^^^^^^^^^^^^^^^^^^^^^^^^
  File "C:\Users\bened\Documents\coding\DPA1\Django-Personal-Assistant\DPA\users\views.py", line 117, in index
    finance_news = get_finance_news()
                   ^^^^^^^^^^^^^^^^^^
  File "C:\Users\bened\Documents\coding\DPA1\Django-Personal-Assistant\DPA\users\finance_scraper.py", line 4, in get_finance_news
    response = requests.get(url)
               ^^^^^^^^
NameError: name 'requests' is not defined

Not Found: /favicon.ico
Not Found: /favicon.ico
Internal Server Error: /files/open/10AlkejTqlDTd2MU0B9adSLirzRl_fAiT/
Traceback (most recent call last):
  File "C:\Users\RollPy\AppData\Local\pypoetry\Cache\virtualenvs\assistant-SImE5PKe-py3.12\Lib\site-packages\django\core\handlers\exception.py", line 55, in inner
    response = get_response(request)
               ^^^^^^^^^^^^^^^^^^^^^
  File "C:\Users\RollPy\AppData\Local\pypoetry\Cache\virtualenvs\assistant-SImE5PKe-py3.12\Lib\site-packages\django\core\handlers\base.py", line 204, in _get_response
    self.check_response(response, callback)
  File "C:\Users\RollPy\AppData\Local\pypoetry\Cache\virtualenvs\assistant-SImE5PKe-py3.12\Lib\site-packages\django\core\handlers\base.py", line 337, in check_response
    raise ValueError(
ValueError: The view files.views.open_file didn't return an HttpResponse object. It returned an unawaited coroutine instead. You may need to add an 'await' into your view.
Internal Server Error: /files/open/10AlkejTqlDTd2MU0B9adSLirzRl_fAiT/
Traceback (most recent call last):
  File "C:\Users\RollPy\AppData\Local\pypoetry\Cache\virtualenvs\assistant-SImE5PKe-py3.12\Lib\site-packages\django\core\handlers\exception.py", line 55, in inner
    response = get_response(request)
               ^^^^^^^^^^^^^^^^^^^^^
  File "C:\Users\RollPy\AppData\Local\pypoetry\Cache\virtualenvs\assistant-SImE5PKe-py3.12\Lib\site-packages\django\core\handlers\base.py", line 204, in _get_response
    self.check_response(response, callback)
  File "C:\Users\RollPy\AppData\Local\pypoetry\Cache\virtualenvs\assistant-SImE5PKe-py3.12\Lib\site-packages\django\core\handlers\base.py", line 337, in check_response
    raise ValueError(
ValueError: The view files.views.open_file didn't return an HttpResponse object. It returned an unawaited coroutine instead. You may need to add an 'await' into your view.
Internal Server Error: /files/download/10AlkejTqlDTd2MU0B9adSLirzRl_fAiT/
Traceback (most recent call last):
  File "C:\Users\RollPy\AppData\Local\pypoetry\Cache\virtualenvs\assistant-SImE5PKe-py3.12\Lib\site-packages\django\core\handlers\exception.py", line 55, in inner
    response = get_response(request)
               ^^^^^^^^^^^^^^^^^^^^^
  File "C:\Users\RollPy\AppData\Local\pypoetry\Cache\virtualenvs\assistant-SImE5PKe-py3.12\Lib\site-packages\django\core\handlers\base.py", line 204, in _get_response
    self.check_response(response, callback)
  File "C:\Users\RollPy\AppData\Local\pypoetry\Cache\virtualenvs\assistant-SImE5PKe-py3.12\Lib\site-packages\django\core\handlers\base.py", line 337, in check_response
    raise ValueError(
ValueError: The view files.views.download_file didn't return an HttpResponse object. It returned an unawaited coroutine instead. You may need to add an 'await' into your view.
Internal Server Error: /files/open/10AlkejTqlDTd2MU0B9adSLirzRl_fAiT/
Traceback (most recent call last):
  File "C:\Users\RollPy\AppData\Local\pypoetry\Cache\virtualenvs\assistant-SImE5PKe-py3.12\Lib\site-packages\django\core\handlers\exception.py", line 55, in inner
    response = get_response(request)
               ^^^^^^^^^^^^^^^^^^^^^
  File "C:\Users\RollPy\AppData\Local\pypoetry\Cache\virtualenvs\assistant-SImE5PKe-py3.12\Lib\site-packages\django\core\handlers\base.py", line 204, in _get_response
    self.check_response(response, callback)
  File "C:\Users\RollPy\AppData\Local\pypoetry\Cache\virtualenvs\assistant-SImE5PKe-py3.12\Lib\site-packages\django\core\handlers\base.py", line 337, in check_response
    raise ValueError(
ValueError: The view files.views.open_file didn't return an HttpResponse object. It returned an unawaited coroutine instead. You may need to add an 'await' into your view.
Internal Server Error: /files/open/10AlkejTqlDTd2MU0B9adSLirzRl_fAiT/
Traceback (most recent call last):
  File "C:\Users\RollPy\AppData\Local\pypoetry\Cache\virtualenvs\assistant-SImE5PKe-py3.12\Lib\site-packages\django\core\handlers\exception.py", line 55, in inner
    response = get_response(request)
               ^^^^^^^^^^^^^^^^^^^^^
  File "C:\Users\RollPy\AppData\Local\pypoetry\Cache\virtualenvs\assistant-SImE5PKe-py3.12\Lib\site-packages\django\core\handlers\base.py", line 197, in _get_response
    response = wrapped_callback(request, *callback_args, **callback_kwargs)
               ^^^^^^^^^^^^^^^^^^^^^^^^^^^^^^^^^^^^^^^^^^^^^^^^^^^^^^^^^^^^
  File "C:\Users\RollPy\AppData\Local\pypoetry\Cache\virtualenvs\assistant-SImE5PKe-py3.12\Lib\site-packages\asgiref\sync.py", line 254, in __call__
    return call_result.result()
           ^^^^^^^^^^^^^^^^^^^^
  File "C:\Users\RollPy\AppData\Local\Programs\Python\Python312\Lib\concurrent\futures\_base.py", line 449, in result
    return self.__get_result()
           ^^^^^^^^^^^^^^^^^^^
  File "C:\Users\RollPy\AppData\Local\Programs\Python\Python312\Lib\concurrent\futures\_base.py", line 401, in __get_result
    raise self._exception
  File "C:\Users\RollPy\AppData\Local\pypoetry\Cache\virtualenvs\assistant-SImE5PKe-py3.12\Lib\site-packages\asgiref\sync.py", line 331, in main_wrap
    result = await self.awaitable(*args, **kwargs)
             ^^^^^^^^^^^^^^^^^^^^^^^^^^^^^^^^^^^^^
  File "C:\Users\RollPy\Documents\GitHub\Django-Personal-Assistant\DPA\files\views.py", line 120, in open_file
    path_to_temporary_file = await sync_to_async(create_file_with_correct_name)(file_id)
                                   ^^^^^^^^^^^^^^^^^^^^^^^^^^^^^^^^^^^^^^^^^^^^
  File "C:\Users\RollPy\AppData\Local\pypoetry\Cache\virtualenvs\assistant-SImE5PKe-py3.12\Lib\site-packages\asgiref\sync.py", line 609, in sync_to_async
    return SyncToAsync(
           ^^^^^^^^^^^^
  File "C:\Users\RollPy\AppData\Local\pypoetry\Cache\virtualenvs\assistant-SImE5PKe-py3.12\Lib\site-packages\asgiref\sync.py", line 399, in __init__
    raise TypeError("sync_to_async can only be applied to sync functions.")
TypeError: sync_to_async can only be applied to sync functions.
Not Found: /favicon.ico
Internal Server Error: /files/delete/1QHwtquLHbwHmHv_XqVwbA-elJKkFmB0t/images
Traceback (most recent call last):
  File "C:\Users\RollPy\AppData\Local\pypoetry\Cache\virtualenvs\assistant-SImE5PKe-py3.12\Lib\site-packages\django\core\handlers\exception.py", line 55, in inner
    response = get_response(request)
               ^^^^^^^^^^^^^^^^^^^^^
  File "C:\Users\RollPy\AppData\Local\pypoetry\Cache\virtualenvs\assistant-SImE5PKe-py3.12\Lib\site-packages\django\core\handlers\base.py", line 204, in _get_response
    self.check_response(response, callback)
  File "C:\Users\RollPy\AppData\Local\pypoetry\Cache\virtualenvs\assistant-SImE5PKe-py3.12\Lib\site-packages\django\core\handlers\base.py", line 337, in check_response
    raise ValueError(
ValueError: The view files.views.delete_file didn't return an HttpResponse object. It returned an unawaited coroutine instead. You may need to add an 'await' into your view.
