Internal Server Error: /files/listfiles/
Traceback (most recent call last):
  File "C:\Users\RollPy\AppData\Local\pypoetry\Cache\virtualenvs\assistant-SImE5PKe-py3.12\Lib\site-packages\django\core\handlers\exception.py", line 55, in inner
    response = get_response(request)
               ^^^^^^^^^^^^^^^^^^^^^
  File "C:\Users\RollPy\AppData\Local\pypoetry\Cache\virtualenvs\assistant-SImE5PKe-py3.12\Lib\site-packages\django\core\handlers\base.py", line 197, in _get_response
    response = wrapped_callback(request, *callback_args, **callback_kwargs)
               ^^^^^^^^^^^^^^^^^^^^^^^^^^^^^^^^^^^^^^^^^^^^^^^^^^^^^^^^^^^^
  File "C:\Users\RollPy\AppData\Local\pypoetry\Cache\virtualenvs\assistant-SImE5PKe-py3.12\Lib\site-packages\django\contrib\auth\decorators.py", line 23, in _wrapper_view
    return view_func(request, *args, **kwargs)
           ^^^^^^^^^^^^^^^^^^^^^^^^^^^^^^^^^^^
  File "C:\Users\RollPy\Documents\GitHub\Django-Personal-Assistant\DPA\files\views.py", line 62, in get_filelist_from_drive
    clean_temp_folder()
  File "C:\Users\RollPy\Documents\GitHub\Django-Personal-Assistant\DPA\files\views.py", line 171, in clean_temp_folder
    for filename in os.listdir(TEMP):
                    ^^^^^^^^^^^^^^^^
FileNotFoundError: [WinError 3] The system cannot find the path specified: 'media/uploads/temp'
